Workbook

Sheet Risk
N1: eqw | O1: ewma | P1: rie
A2: CoVaR Multiplier (c) | C2: {=SQRT(MMULT(TRANSPOSE(C11:C28),K11:K28))} -> 372682.33 | M2: CoVaR Multiplier (c) | N2: 198545.56 | O2: 299271.2 | P2: 205307
B3: 99% VaR | C3: =C2*2.326 -> 866859.11 | M3: 99% CoVaR | N3: 461816.98 | O3: 696104.82 | P3: 477544.09
B4: 95% VaR | C4: =C2*1.644 -> 612689.75 | M4: 95% CoVaR | N4: 326408.91 | O4: 492001.86 | P4: 337524.71
A5: 1Y | B5: Hist 99% | C5: =Hist!B1*-1 -> 687389.62 | M5: Hist 99% 300 obs | N5: =C5 -> 687389.62
A6: all | B6: Hist 99% | C6: =Hist!B2*-1 -> 907260.8 | M6: Hist 99% 546 obs | N6: =C6 -> 907260.8
M7: 99% Last 300 obs Hist vs CoVar | N7: =N3-$C5 -> -225572.64 | O7: =O3-$C5 -> 8715.1963 | P7: =P3-$C5 -> -209845.53
M8: 99% Last 546 obs Hist vs CoVar | N8: =N3-$C6 -> -445443.81 | O8: =O3-$C6 -> -211155.98 | P8: =P3-$C6 -> -429716.7
A10: Type | B10: Bucket | C10: Risk | D10: Allocation | E10: Min Trade | F10: c Reduc | G10: %c Reduc | K10: Q*S | L10: diag(Q)
A11: USD Swap | B11: 1mo | C11: -4000 | D11: =(C11*K11)/$C$2 -> 1321.2642 | E11: =-K11/L11 -> 85773.673 | F11: =$C$2-SQRT($C$2^2-(K11^2)/L11) -> 14446.198 | G11: =F11/$C$2 -> 0.038762766 | K11: {=MMULT(Q!B2:S19,C11:C28)} -> -123102.96 | L11: 1.4352068
A12: USD Swap | B12: 2mo | C12: -2223 | D12: =(C12*K12)/$C$2 -> 477.54746 | E12: =-K12/L12 -> 37761.157 | F12: =$C$2-SQRT($C$2^2-(K12^2)/L12) -> 4078.2621 | G12: =F12/$C$2 -> 0.010942998 | K12: -80060.054 | L12: 2.1201695
A13: USD Swap | B13: 3mo | C13: =4590 -> 4590 | D13: =(C13*K13)/$C$2 -> -1110.1758 | E13: =-K13/L13 -> 37384.203 | F13: =$C$2-SQRT($C$2^2-(K13^2)/L13) -> 4548.7881 | G13: =F13/$C$2 -> 0.012205537 | K13: -90140.066 | L13: 2.4111806
A14: USD Swap | B14: 4mo | C14: -3445 | D14: =(C14*K14)/$C$2 -> -15.772968 | E14: =-K14/L14 -> -1526.247 | F14: =$C$2-SQRT($C$2^2-(K14^2)/L14) -> 3.4939852 | G14: =F14/$C$2 -> 9.375237e-06 | K14: 1706.3299 | L14: 1.1179907
A15: USD Swap | B15: 6mo | C15: =5435 -> 5435 | D15: =(C15*K15)/$C$2 -> -3327.116 | E15: =-K15/L15 -> 59211.73 | F15: =$C$2-SQRT($C$2^2-(K15^2)/L15) -> 18587.179 | G15: =F15/$C$2 -> 0.049874054 | K15: -228143.03 | L15: 3.8530039
A16: USD Swap | B16: 1y | C16: -2000 | D16: =(C16*K16)/$C$2 -> 3318.9202 | E16: =-K16/L16 -> 64954.514 | F16: =$C$2-SQRT($C$2^2-(K16^2)/L16) -> 58483.499 | G16: =F16/$C$2 -> 0.15692587 | K16: -618451.46 | L16: 9.5213006
A17: USD Swap | B17: 2y | C17: 4564 | D17: =(C17*K17)/$C$2 -> -13486.19 | E17: =-K17/L17 -> 46711.935 | F17: =$C$2-SQRT($C$2^2-(K17^2)/L17) -> 76961.157 | G17: =F17/$C$2 -> 0.20650605 | K17: -1101241.2 | L17: 23.575157
A18: USD Swap | B18: 3y | C18: -2223 | D18: =(C18*K18)/$C$2 -> 6435.7801 | E18: =-K18/L18 -> 46393.742 | F18: =$C$2-SQRT($C$2^2-(K18^2)/L18) -> 74629.177 | G18: =F18/$C$2 -> 0.20024877 | K18: -1078948.1 | L18: 23.256328
A19: USD Swap | B19: 5y | C19: -100544 | D19: =(C19*K19)/$C$2 -> 261346.75 | E19: =-K19/L19 -> 43802.924 | F19: =$C$2-SQRT($C$2^2-(K19^2)/L19) -> 62103.505 | G19: =F19/$C$2 -> 0.16663925 | K19: -968723.29 | L19: 22.115494
A20: USD Swap | B20: 7y | C20: 1 | D20: =(C20*K20)/$C$2 -> -2.2615535 | E20: =-K20/L20 -> 40863.09 | F20: =$C$2-SQRT($C$2^2-(K20^2)/L20) -> 49493.483 | G20: =F20/$C$2 -> 0.1328034 | K20: -842841.02 | L20: 20.625974
A21: USD Swap | B21: 10y | C21: =50323 -> 50323 | D21: =(C21*K21)/$C$2 -> -90945.145 | E21: =-K21/L21 -> 41415.768 | F21: =$C$2-SQRT($C$2^2-(K21^2)/L21) -> 39519.176 | G21: =F21/$C$2 -> 0.10603984 | K21: -673522.02 | L21: 16.262454
A22: USD Swap | B22: 20y | C22: =25323 -> 25323 | D22: =(C22*K22)/$C$2 -> -33642.196 | E22: =-K22/L22 -> 32304.817 | F22: =$C$2-SQRT($C$2^2-(K22^2)/L22) -> 22115.005 | G22: =F22/$C$2 -> 0.059340095 | K22: -495117.18 | L22: 15.326419
A23: USD Swap | B23: 30y | C23: 1 | D23: =(C23*K23)/$C$2 -> -0.62141473 | E23: =-K23/L23 -> 15044.554 | F23: =$C$2-SQRT($C$2^2-(K23^2)/L23) -> 4704.1424 | G23: =F23/$C$2 -> 0.012622392 | K23: -231590.29 | L23: 15.39363
A24: FX | B24: USDBRL | C24: 1 | D24: =(C24*K24)/$C$2 -> -0.44239713 | E24: =-K24/L24 -> 263676.42 | F24: =$C$2-SQRT($C$2^2-(K24^2)/L24) -> 63782.928 | G24: =F24/$C$2 -> 0.17114556 | K24: -164873.59 | L24: 0.62528758
A25: FX | B25: USDCOP | C25: -100000 | D25: =(C25*K25)/$C$2 -> 66445.083 | E25: =-K25/L25 -> 174605.75 | F25: =$C$2-SQRT($C$2^2-(K25^2)/L25) -> 63401.458 | G25: =F25/$C$2 -> 0.17012199 | K25: -247629.08 | L25: 1.4182184
A26: FX | B26: USDCLP | C26: 100000 | D26: =(C26*K26)/$C$2 -> 15777.45 | E26: =-K26/L26 -> -48334.779 | F26: =$C$2-SQRT($C$2^2-(K26^2)/L26) -> 3832.7057 | G26: =F26/$C$2 -> 0.010284109 | K26: 58799.769 | L26: 1.2165106
A27: FX | B27: USDPEN | C27: =(-25000000)*0.01 -> -250000 | D27: =(C27*K27)/$C$2 -> 113659.77 | E27: =-K27/L27 -> 401715.23 | F27: =$C$2-SQRT($C$2^2-(K27^2)/L27) -> 106548.68 | G27: =F27/$C$2 -> 0.28589678 | K27: -169435.95 | L27: 0.42178125
A28: FX | B28: USDMXN | C28: =(-10000000)*0.01 -> -100000 | D28: =(C28*K28)/$C$2 -> 46429.697 | E28: =-K28/L28 -> 361680.56 | F28: =$C$2-SQRT($C$2^2-(K28^2)/L28) -> 96442.176 | G28: =F28/$C$2 -> 0.2587785 | K28: -173035.28 | L28: 0.47842018

Sheet Q
B1: 1mo | C1: 2mo | D1: 3mo | E1: 4mo | F1: 6mo | G1: 1y | H1: 2y | I1: 3y | J1: 5y | K1: 7y | L1: 10y | M1: 20y | N1: 30y | O1: USDBRL | P1: USDCOP | Q1: USDCLP | R1: USDPEN | S1: USDMXN
A2: 1mo | B2: 1.4352068 | C2: 0.71559403 | D2: 0.28725654 | E2: 0.22367614 | F2: 0.068100075 | G2: 0.35063582 | H2: 0.52161864 | I2: 0.53362192 | J2: 0.27183172 | K2: 0.13539027 | L2: -0.03674077 | M2: -0.27440652 | N2: -0.58282893 | O2: 0.12562727 | P2: 0.33922941 | Q2: -0.060095522 | R2: 0.10710348 | S2: 0.14345151
A3: 2mo | B3: 0.71559403 | C3: 2.1201695 | D3: 0.75240879 | E3: 0.2749326 | F3: 0.51441232 | G3: 0.83032075 | H3: 1.1131113 | I3: 1.1734039 | J3: 0.51587879 | K3: 0.23485984 | L3: 0.00064348763 | M3: -0.67510851 | N3: -0.90968579 | O3: 0.021422523 | P3: 0.1675174 | Q3: 0.32538114 | R3: 0.11344612 | S3: -0.029098081
A4: 3mo | B4: 0.28725654 | C4: 0.75240879 | D4: 2.4111806 | E4: 0.79910394 | F4: 2.3338225 | G4: 2.5084867 | H4: 3.5782707 | I4: 3.5371317 | J4: 3.6654033 | K4: 3.1019776 | L4: 2.3717489 | M4: 1.682762 | N4: 1.3029264 | O4: -0.08365038 | P4: -0.30393002 | Q4: 0.43502168 | R4: -0.033058402 | S4: -0.12635742
A5: 4mo | B5: 0.22367614 | C5: 0.2749326 | D5: 0.79910394 | E5: 1.1179907 | F5: 0.96358575 | G5: 1.295868 | H5: 1.4651771 | I5: 1.4500788 | J5: 1.5907532 | K5: 1.247977 | L5: 0.90825076 | M5: 0.63041082 | N5: 0.62213527 | O5: -0.26789166 | P5: -0.089806925 | Q5: 0.12465396 | R5: -0.198267 | S5: -0.24543362
A6: 6mo | B6: 0.068100075 | C6: 0.51441232 | D6: 2.3338225 | E6: 0.96358575 | F6: 3.8530039 | G6: 4.0201477 | H6: 5.6726295 | I6: 5.6035234 | J6: 5.7111237 | K6: 4.9258685 | L6: 3.8127522 | M6: 2.9655384 | N6: 2.4443085 | O6: 0.12537733 | P6: -0.225098 | Q6: 0.5109687 | R6: 0.083872215 | S6: 0.058461523
A7: 1y | B7: 0.35063582 | C7: 0.83032075 | D7: 2.5084867 | E7: 1.295868 | F7: 4.0201477 | G7: 9.5213006 | H7: 13.180848 | I7: 13.109375 | J7: 12.048578 | K7: 10.585496 | L7: 8.5498965 | M7: 6.8363463 | N7: 5.7145259 | O7: 0.040013075 | P7: -0.15352504 | Q7: 0.17624832 | R7: 0.15508244 | S7: 0.42259018
A8: 2y | B8: 0.52161864 | C8: 1.1131113 | D8: 3.5782707 | E8: 1.4651771 | F8: 5.6726295 | G8: 13.180848 | H8: 23.575157 | I8: 22.321996 | J8: 21.374197 | K8: 19.678458 | L8: 16.700193 | M8: 14.289667 | N8: 12.017395 | O8: 0.82373895 | P8: -0.60453093 | Q8: 0.27339761 | R8: 0.76149006 | S8: 1.2116792
A9: 3y | B9: 0.53362192 | C9: 1.1734039 | D9: 3.5371317 | E9: 1.4500788 | F9: 5.6035234 | G9: 13.109375 | H9: 22.321996 | I9: 23.256328 | J9: 22.047672 | K9: 20.645032 | L9: 17.514106 | M9: 14.661103 | N9: 12.519987 | O9: 0.69946227 | P9: -0.55078428 | Q9: 0.349042 | R9: 0.69578142 | S9: 0.91795622
A10: 5y | B10: 0.27183172 | C10: 0.51587879 | D10: 3.6654033 | E10: 1.5907532 | F10: 5.7111237 | G10: 12.048578 | H10: 21.374197 | I10: 22.047672 | J10: 22.115494 | K10: 20.978807 | L10: 18.03392 | M10: 15.753548 | N10: 13.931889 | O10: 0.69649641 | P10: -0.7020328 | Q10: 0.1787057 | R10: 0.47918026 | S10: 0.84498147
A11: 7y | B11: 0.13539027 | C11: 0.23485984 | D11: 3.1019776 | E11: 1.247977 | F11: 4.9258685 | G11: 10.585496 | H11: 19.678458 | I11: 20.645032 | J11: 20.978807 | K11: 20.625974 | L11: 17.932341 | M11: 15.915839 | N11: 14.519913 | O11: 0.76715763 | P11: -0.72594993 | Q11: 0.0959062 | R11: 0.375818 | S11: 0.85655752
A12: 10y | B12: -0.03674077 | C12: 0.00064348763 | D12: 2.3717489 | E12: 0.90825076 | F12: 3.8127522 | G12: 8.5498965 | H12: 16.700193 | I12: 17.514106 | J12: 18.03392 | K12: 17.932341 | L12: 16.262454 | M12: 14.961847 | N12: 14.034064 | O12: 0.66128549 | P12: -0.61093901 | Q12: -0.18435586 | R12: 0.28964251 | S12: 0.7666543
A13: 20y | B13: -0.27440652 | C13: -0.67510851 | D13: 1.682762 | E13: 0.63041082 | F13: 2.9655384 | G13: 6.8363463 | H13: 14.289667 | I13: 14.661103 | J13: 15.753548 | K13: 15.915839 | L13: 14.961847 | M13: 15.326419 | N13: 14.822194 | O13: 0.61929367 | P13: -0.73505452 | Q13: -0.67997965 | R13: 0.11706534 | S13: 0.71722812
... A19: USDMXN | B19: 0.14345151 | C19: -0.029098081 | D19: -0.12635742 | E19: -0.24543362 | F19: 0.058461523 | G19: 0.42259018 | H19: 1.2116792 | I19: 0.91795622 | J19: 0.84498147 | K19: 0.85655752 | L19: 0.7666543 | M19: 0.71722812 | N19: 0.4279753 | O19: 0.36935175 | P19: 0.2288718 | Q19: -0.082502255 | R19: 0.27424347 | S19: 0.47842018

Sheet Hist
A1: Hist VaR | B1: =SMALL(AN5:AN304,4) -> -687389.62
A2: Hist VaR | B2: =SMALL(AN5:AN550,4) -> -907260.8
A3: Risk | B3: {=TRANSPOSE(Risk!C11:C23)} -> -4000 | C3: -2223 | D3: 4590 | E3: -3445 | F3: 5435 | G3: -2000 | H3: 4564 | I3: -2223 | J3: -100544 | K3: 1 | L3: 50323 | M3: 25323 | N3: 1 | O3: {=TRANSPOSE(Risk!C24:C28)/0.01} -> 100 | P3: -10000000 | Q3: 10000000 | R3: -25000000 | S3: -10000000
A4: dates | B4: 1mo | C4: 2mo | D4: 3mo | E4: 4mo | F4: 6mo | G4: 1y | H4: 2y | I4: 3y | J4: 5y | K4: 7y | L4: 10y | M4: 20y | N4: 30y | O4: USDBRL | P4: USDCOP | Q4: USDCLP | R4: USDPEN | S4: USDMXN | U4: dates | V4: 1mo | W4: 2mo | X4: 3mo | Y4: 4mo | Z4: 6mo | AA4: 1y | AB4: 2y | AC4: 3y | AD4: 5y | AE4: 7y | AF4: 10y | AG4: 20y | AH4: 30y | AI4: USDBRL | AJ4: USDCOP | AK4: USDCLP | AL4: USDPEN | AM4: USDMXN | AN4: PnL | AO4: chge | AP4: vol
A5: 46093 | B5: =(B554-B555)*100 -> 1 | C5: =(C554-C555)*100 -> 2 | D5: =(D554-D555)*100 -> 1 | E5: =(E554-E555)*100 -> 0 | F5: =(F554-F555)*100 -> 2 | G5: =(G554-G555)*100 -> 6 | H5: =(H554-H555)*100 -> 12 | I5: =(I554-I555)*100 -> 11 | ... N5: =(N554-N555)*100 -> 2 | O5: =LN(O554/O555) -> 0.0087803654 | P5: =LN(P554/P555) -> -0.0059286304 | Q5: =LN(Q554/Q555) -> 0.0024251919 | R5: =LN(R554/R555) -> 0.0075757938 | S5: =LN(S554/S555) -> 0.0098607855 | U5: 46093 | V5: =B5*B$3 -> -4000 | W5: =C5*C$3 -> -4446 | X5: =D5*D$3 -> 4590 | Y5: =E5*E$3 -> 0 | Z5: =F5*F$3 -> 10870 | AA5: =G5*G$3 -> -12000 | AB5: =H5*H$3 -> 54768 | AC5: =I5*I$3 -> -24453 | ... AM5: =S5*S$3 -> -98607.855 | AN5: =SUM(V5:AM5) -> -680790.6 | AO5: =AN5/AN6-1 -> 2.375591 | AP5: =STDEV(AO5:AO25) -> 23.037163
A6: 46092 | B6: =(B556-B555)*100 -> 0 | C6: =(C556-C555)*100 -> 1 | D6: =(D556-D555)*100 -> 0 | E6: =(E556-E555)*100 -> 0 | F6: =(F556-F555)*100 -> 0 | G6: =(G556-G555)*100 -> -4 | H6: =(H556-H555)*100 -> -7 | I6: =(I556-I555)*100 -> -6 | ... N6: =(N556-N555)*100 -> -8 | O6: =LN(O555/O556) -> -0.0005038174 | P6: =LN(P555/P556) -> 0.0021210635 | Q6: =LN(Q555/Q556) -> -0.025050342 | R6: =LN(R555/R556) -> -0.0011692489 | S6: =LN(S555/S556) -> 0.0045093539 | U6: 46092 | V6: =B6*B$3 -> 0 | W6: =C6*C$3 -> -2223 | X6: =D6*D$3 -> 0 | Y6: =E6*E$3 -> 0 | Z6: =F6*F$3 -> 0 | AA6: =G6*G$3 -> 8000 | AB6: =H6*H$3 -> -31948 | AC6: =I6*I$3 -> 13338 | ... AM6: =S6*S$3 -> -45093.539 | AN6: =SUM(V6:AM6) -> -201680.42 | AO6: =AN6/AN7-1 -> -1.3416782 | AP6: =STDEV(AO6:AO26) -> 23.049109
A7: 46091 | B7: =(B557-B556)*100 -> 0 | C7: =(C557-C556)*100 -> 1 | D7: =(D557-D556)*100 -> 0 | E7: =(E557-E556)*100 -> -1 | F7: =(F557-F556)*100 -> 0 | G7: =(G557-G556)*100 -> 0 | H7: =(H557-H556)*100 -> -1 | I7: =(I557-I556)*100 -> 0 | ... N7: =(N557-N556)*100 -> -6 | O7: =LN(O556/O557) -> -0.0099658673 | P7: =LN(P556/P557) -> -0.018743724 | Q7: =LN(Q556/Q557) -> -0.0058755854 | R7: =LN(R556/R557) -> -0.018811146 | S7: =LN(S556/S557) -> -0.0045829231 | U7: 46091 | V7: =B7*B$3 -> 0 | W7: =C7*C$3 -> -2223 | X7: =D7*D$3 -> 0 | Y7: =E7*E$3 -> 3445 | Z7: =F7*F$3 -> 0 | AA7: =G7*G$3 -> 0 | AB7: =H7*H$3 -> -4564 | AC7: =I7*I$3 -> 0 | ... AM7: =S7*S$3 -> 45829.231 | AN7: =SUM(V7:AM7) -> 590264.29 | AO7: =AN7/AN8-1 -> 0.9687389 | AP7: =STDEV(AO7:AO27) -> 23.047272
A8: 46090 | B8: =(B558-B557)*100 -> 0 | C8: =(C558-C557)*100 -> 0 | D8: =(D558-D557)*100 -> -2 | E8: =(E558-E557)*100 -> -1 | F8: =(F558-F557)*100 -> -2 | G8: =(G558-G557)*100 -> -1 | H8: =(H558-H557)*100 -> 0 | I8: =(I558-I557)*100 -> 1 | ... N8: =(N558-N557)*100 -> 5 | O8: =LN(O557/O558) -> -0.014074948 | P8: =LN(P557/P558) -> -0.00079607275 | Q8: =LN(Q557/Q558) -> 0.015415027 | R8: =LN(R557/R558) -> 0.0028710901 | S8: =LN(S557/S558) -> -0.0074589135 | U8: 46090 | V8: =B8*B$3 -> 0 | W8: =C8*C$3 -> 0 | X8: =D8*D$3 -> -9180 | Y8: =E8*E$3 -> 3445 | Z8: =F8*F$3 -> -10870 | AA8: =G8*G$3 -> 2000 | AB8: =H8*H$3 -> 0 | AC8: =I8*I$3 -> -2223 | ... AM8: =S8*S$3 -> 74589.135 | AN8: =SUM(V8:AM8) -> 299818.47 | AO8: =AN8/AN9-1 -> -1.9819339 | AP8: =STDEV(AO8:AO28) -> 23.077661
A9: 46087 | B9: =(B559-B558)*100 -> 0 | C9: =(C559-C558)*100 -> 0 | D9: =(D559-D558)*100 -> 1 | E9: =(E559-E558)*100 -> 1 | F9: =(F559-F558)*100 -> 2 | G9: =(G559-G558)*100 -> 4 | H9: =(H559-H558)*100 -> 1 | I9: =(I559-I558)*100 -> 0 | ... N9: =(N559-N558)*100 -> -3 | O9: =LN(O558/O559) -> 0.0081847037 | P9: =LN(P558/P559) -> -0.0013253812 | Q9: =LN(Q558/Q559) -> 0.013889729 | R9: =LN(R558/R559) -> 0.011276684 | S9: =LN(S558/S559) -> 0.00075294862 | U9: 46087 | V9: =B9*B$3 -> 0 | W9: =C9*C$3 -> 0 | X9: =D9*D$3 -> 4590 | Y9: =E9*E$3 -> -3445 | Z9: =F9*F$3 -> 10870 | AA9: =G9*G$3 -> -8000 | AB9: =H9*H$3 -> 4564 | AC9: =I9*I$3 -> 0 | ... AM9: =S9*S$3 -> -7529.4862 | AN9: =SUM(V9:AM9) -> -305334.68 | AO9: =AN9/AN10-1 -> -0.097408055 | AP9: =STDEV(AO9:AO29) -> 23.042688
A10: 46086 | B10: =(B560-B559)*100 -> 0 | C10: =(C560-C559)*100 -> 3 | D10: =(D560-D559)*100 -> 1 | E10: =(E560-E559)*100 -> 0 | F10: =(F560-F559)*100 -> 0 | G10: =(G560-G559)*100 -> -1 | H10: =(H560-H559)*100 -> -3 | I10: =(I560-I559)*100 -> -4 | ... N10: =(N560-N559)*100 -> -2 | O10: =LN(O559/O560) -> 0.0068113377 | P10: =LN(P559/P560) -> 0.0074448629 | Q10: =LN(Q559/Q560) -> -0.012412314 | R10: =LN(R559/R560) -> 0.008175228 | S10: =LN(S559/S560) -> 0.013058473 | U10: 46086 | V10: =B10*B$3 -> 0 | W10: =C10*C$3 -> -6669 | X10: =D10*D$3 -> 4590 | Y10: =E10*E$3 -> 0 | Z10: =F10*F$3 -> 0 | AA10: =G10*G$3 -> 2000 | AB10: =H10*H$3 -> -13692 | AC10: =I10*I$3 -> 8892 | ... AM10: =S10*S$3 -> -130584.73 | AN10: =SUM(V10:AM10) -> -338286.51 | AO10: =AN10/AN11-1 -> -1.5045908 | AP10: =STDEV(AO10:AO30) -> 23.079147
A11: 46085 | B11: =(B561-B560)*100 -> 0 | C11: =(C561-C560)*100 -> -1 | D11: =(D561-D560)*100 -> 0 | E11: =(E561-E560)*100 -> -1 | F11: =(F561-F560)*100 -> 0 | G11: =(G561-G560)*100 -> -3 | H11: =(H561-H560)*100 -> -3 | I11: =(I561-I560)*100 -> -5 | ... N11: =(N561-N560)*100 -> -2 | O11: =LN(O560/O561) -> -0.01484473 | P11: =LN(P560/P561) -> -0.014045547 | Q11: =LN(Q560/Q561) -> 0.024697854 | R11: =LN(R560/R561) -> -0.0011719896 | S11: =LN(S560/S561) -> -0.0044039292 | U11: 46085 | V11: =B11*B$3 -> 0 | W11: =C11*C$3 -> 2223 | X11: =D11*D$3 -> 0 | Y11: =E11*E$3 -> 3445 | Z11: =F11*F$3 -> 0 | AA11: =G11*G$3 -> 6000 | AB11: =H11*H$3 -> -13692 | AC11: =I11*I$3 -> 11115 | ... AM11: =S11*S$3 -> 44039.292 | AN11: =SUM(V11:AM11) -> 670417.55 | AO11: =AN11/AN12-1 -> -2.2011521 | AP11: =STDEV(AO11:AO31) -> 23.070063
A12: 46084 | B12: =(B562-B561)*100 -> -1 | C12: =(C562-C561)*100 -> 0 | D12: =(D562-D561)*100 -> 1 | E12: =(E562-E561)*100 -> 1 | F12: =(F562-F561)*100 -> 0 | G12: =(G562-G561)*100 -> -1 | H12: =(H562-H561)*100 -> -4 | I12: =(I562-I561)*100 -> -1 | ... N12: =(N562-N561)*100 -> 0 | O12: =LN(O561/O562) -> 0.016574069 | P12: =LN(P561/P562) -> 0.013511929 | Q12: =LN(Q561/Q562) -> 0.014582002 | R12: =LN(R561/R562) -> 0.01534406 | S12: =LN(S561/S562) -> 0.020125529 | U12: 46084 | V12: =B12*B$3 -> 4000 | W12: =C12*C$3 -> 0 | X12: =D12*D$3 -> 4590 | Y12: =E12*E$3 -> -3445 | Z12: =F12*F$3 -> 0 | AA12: =G12*G$3 -> 2000 | AB12: =H12*H$3 -> -18256 | AC12: =I12*I$3 -> 2223 | ... AM12: =S12*S$3 -> -201255.29 | AN12: =SUM(V12:AM12) -> -558145.41 | AO12: =AN12/AN13-1 -> -2.1631894 | AP12: =STDEV(AO12:AO32) -> 23.06308
A13: 46083 | B13: =(B563-B562)*100 -> 0 | C13: =(C563-C562)*100 -> -1 | D13: =(D563-D562)*100 -> -5 | E13: =(E563-E562)*100 -> -1 | F13: =(F563-F562)*100 -> -8 | G13: =(G563-G562)*100 -> -6 | H13: =(H563-H562)*100 -> -9 | I13: =(I563-I562)*100 -> -10 | ... N13: =(N563-N562)*100 -> -6 | O13: =LN(O562/O563) -> 0.0097788005 | P13: =LN(P562/P563) -> -0.00087984755 | Q13: =LN(Q562/Q563) -> 0.011797436 | R13: =LN(R562/R563) -> 0.0029779653 | S13: =LN(S562/S563) -> 0.0030999153 | U13: 46083 | V13: =B13*B$3 -> 0 | W13: =C13*C$3 -> 2223 | X13: =D13*D$3 -> -22950 | Y13: =E13*E$3 -> 3445 | Z13: =F13*F$3 -> -43480 | AA13: =G13*G$3 -> 12000 | AB13: =H13*H$3 -> -41076 | AC13: =I13*I$3 -> 22230 | ... AM13: =S13*S$3 -> -30999.153 | AN13: =SUM(V13:AM13) -> 479840.53 | AO13: =AN13/AN14-1 -> -13.512829 | AP13: =STDEV(AO13:AO33) -> 23.015088
A14: 46080 | B14: =(B564-B563)*100 -> 0 | C14: =(C564-C563)*100 -> 2 | D14: =(D564-D563)*100 -> 1 | E14: =(E564-E563)*100 -> 1 | F14: =(F564-F563)*100 -> 1 | G14: =(G564-G563)*100 -> 4 | H14: =(H564-H563)*100 -> 4 | I14: =(I564-I563)*100 -> 7 | ... N14: =(N564-N563)*100 -> 3 | O14: =LN(O563/O564) -> 0.0021969271 | P14: =LN(P563/P564) -> -0.020495818 | Q14: =LN(Q563/Q564) -> 0.0042006846 | R14: =LN(R563/R564) -> -0.00059630294 | S14: =LN(S563/S564) -> 0.0021378701 | U14: 46080 | V14: =B14*B$3 -> 0 | W14: =C14*C$3 -> -4446 | X14: =D14*D$3 -> 4590 | Y14: =E14*E$3 -> -3445 | Z14: =F14*F$3 -> 5435 | AA14: =G14*G$3 -> -8000 | AB14: =H14*H$3 -> 18256 | AC14: =I14*I$3 -> -15561 | ... AM14: =S14*S$3 -> -21378.701 | AN14: =SUM(V14:AM14) -> -38347.884 | AO14: =AN14/AN15-1 -> -0.93972019 | AP14: =STDEV(AO14:AO34) -> 22.659874
A15: 46079 | B15: =(B565-B564)*100 -> -3 | C15: =(C565-C564)*100 -> -2 | D15: =(D565-D564)*100 -> 1 | E15: =(E565-E564)*100 -> 0 | F15: =(F565-F564)*100 -> 1 | G15: =(G565-G564)*100 -> 1 | H15: =(H565-H564)*100 -> 3 | I15: =(I565-I564)*100 -> 3 | ... N15: =(N565-N564)*100 -> 3 | O15: =LN(O564/O565) -> -0.0011282292 | P15: =LN(P564/P565) -> 0.038051684 | Q15: =LN(Q564/Q565) -> -0.0090311362 | R15: =LN(R564/R565) -> 0 | S15: =LN(S564/S565) -> 0.0021599349 | U15: 46079 | V15: =B15*B$3 -> 12000 | W15: =C15*C$3 -> 4446 | X15: =D15*D$3 -> 4590 | Y15: =E15*E$3 -> 0 | Z15: =F15*F$3 -> 5435 | AA15: =G15*G$3 -> -2000 | AB15: =H15*H$3 -> 13692 | AC15: =I15*I$3 -> -6669 | ... AM15: =S15*S$3 -> -21599.349 | AN15: =SUM(V15:AM15) -> -636164.66 | AO15: =AN15/AN16-1 -> 27.166203 | AP15: =STDEV(AO15:AO35) -> 22.648889
A16: 46078 | B16: =(B566-B565)*100 -> 1 | C16: =(C566-C565)*100 -> 0 | D16: =(D566-D565)*100 -> 0 | E16: =(E566-E565)*100 -> 2 | F16: =(F566-F565)*100 -> 0 | G16: =(G566-G565)*100 -> -1 | H16: =(H566-H565)*100 -> -2 | I16: =(I566-I565)*100 -> -2 | ... N16: =(N566-N565)*100 -> 0 | O16: =LN(O565/O566) -> -0.0046937516 | P16: =LN(P565/P566) -> -0.0046001975 | Q16: =LN(Q565/Q566) -> -0.0022278023 | R16: =LN(R565/R566) -> -0.00029801818 | S16: =LN(S565/S566) -> -0.0010135963 | U16: 46078 | V16: =B16*B$3 -> -4000 | W16: =C16*C$3 -> 0 | X16: =D16*D$3 -> 0 | Y16: =E16*E$3 -> -6890 | Z16: =F16*F$3 -> 0 | AA16: =G16*G$3 -> 2000 | AB16: =H16*H$3 -> -9128 | AC16: =I16*I$3 -> 4446 | ... AM16: =S16*S$3 -> 10135.963 | AN16: =SUM(V16:AM16) -> -22586.1 | AO16: =AN16/AN17-1 -> -1.1326296 | AP16: =STDEV(AO16:AO36) -> 22.114736
A17: 46077 | B17: =(B567-B566)*100 -> 0 | C17: =(C567-C566)*100 -> 1 | D17: =(D567-D566)*100 -> 0 | E17: =(E567-E566)*100 -> 0 | F17: =(F567-F566)*100 -> 0 | G17: =(G567-G566)*100 -> -2 | H17: =(H567-H566)*100 -> 0 | I17: =(I567-I566)*100 -> -2 | ... N17: =(N567-N566)*100 -> 0 | O17: =LN(O566/O567) -> 0.00090987413 | P17: =LN(P566/P567) -> 0.0056042273 | Q17: =LN(Q566/Q567) -> 0.00018449972 | R17: =LN(R566/R567) -> -0.00059577005 | S17: =LN(S566/S567) -> -0.0052611529 | U17: 46077 | V17: =B17*B$3 -> 0 | W17: =C17*C$3 -> -2223 | X17: =D17*D$3 -> 0 | Y17: =E17*E$3 -> 0 | Z17: =F17*F$3 -> 0 | AA17: =G17*G$3 -> 4000 | AB17: =H17*H$3 -> 0 | AC17: =I17*I$3 -> 4446 | ... AM17: =S17*S$3 -> 52611.529 | AN17: =SUM(V17:AM17) -> 170294.6 | AO17: =AN17/AN18-1 -> -1.7148929 | AP17: =STDEV(AO17:AO37) -> 22.101812
... A525: 45330 | B525: =(B1075-B1074)*100 -> -2 | C525: =(C1075-C1074)*100 -> -2 | D525: =(D1075-D1074)*100 -> -1 | E525: =(E1075-E1074)*100 -> -2 | F525: =(F1075-F1074)*100 -> -1 | G525: =(G1075-G1074)*100 -> 0 | H525: =(H1075-H1074)*100 -> -5 | I525: =(I1075-I1074)*100 -> -6 | ... N525: =(N1075-N1074)*100 -> -5 | O525: =LN(O1074/O1075) -> 0.003943429 | P525: =LN(P1074/P1075) -> -0.002781643 | Q525: =LN(Q1074/Q1075) -> -0.0020129531 | R525: =LN(R1074/R1075) -> 0.0049344341 | S525: =LN(S1074/S1075) -> 0.0053859989 | U525: 45330 | V525: =B525*B$3 -> 8000 | W525: =C525*C$3 -> 4446 | X525: =D525*D$3 -> -4590 | Y525: =E525*E$3 -> 6890 | Z525: =F525*F$3 -> -5435 | AA525: =G525*G$3 -> 0 | AB525: =H525*H$3 -> -22820 | AC525: =I525*I$3 -> 13338 | ... AM525: =S525*S$3 -> -53859.989 | AN525: =SUM(V525:AM525) -> -20327.55 | AO525: =AN525/AN526-1 -> -1.0698045 | AP525: =STDEV(AO525:AO545) -> 3.0283272
A526: 45329 | B526: =(B1076-B1075)*100 -> 1 | C526: =(C1076-C1075)*100 -> 1 | D526: =(D1076-D1075)*100 -> 1 | E526: =(E1076-E1075)*100 -> 1 | F526: =(F1076-F1075)*100 -> 0 | G526: =(G1076-G1075)*100 -> -1 | H526: =(H1076-H1075)*100 -> -2 | I526: =(I1076-I1075)*100 -> -2 | ... N526: =(N1076-N1075)*100 -> -2 | O526: =LN(O1075/O1076) -> -0.0015913146 | P526: =LN(P1075/P1076) -> 0.0010106115 | Q526: =LN(Q1075/Q1076) -> -0.0062134818 | R526: =LN(R1075/R1076) -> -0.0051934679 | S526: =LN(S1075/S1076) -> 0.00096107648 | U526: 45329 | V526: =B526*B$3 -> -4000 | W526: =C526*C$3 -> -2223 | X526: =D526*D$3 -> 4590 | Y526: =E526*E$3 -> -3445 | Z526: =F526*F$3 -> 0 | AA526: =G526*G$3 -> 2000 | AB526: =H526*H$3 -> -9128 | AC526: =I526*I$3 -> 4446 | ... AM526: =S526*S$3 -> -9610.7648 | AN526: =SUM(V526:AM526) -> 291206.84 | AO526: =AN526/AN527-1 -> -2.1312612
A527: 45328 | B527: =(B1077-B1076)*100 -> 1 | C527: =(C1077-C1076)*100 -> 0 | D527: =(D1077-D1076)*100 -> -2 | E527: =(E1077-E1076)*100 -> 1 | F527: =(F1077-F1076)*100 -> 2 | G527: =(G1077-G1076)*100 -> 5 | H527: =(H1077-H1076)*100 -> 7 | I527: =(I1077-I1076)*100 -> 13 | ... N527: =(N1077-N1076)*100 -> 6 | O527: =LN(O1076/O1077) -> -0.0073395561 | P527: =LN(P1076/P1077) -> -0.00025274864 | Q527: =LN(Q1076/Q1077) -> 0.012518786 | R527: =LN(R1076/R1077) -> 0 | S527: =LN(S1076/S1077) -> -0.0053153513 | U527: 45328 | V527: =B527*B$3 -> -4000 | W527: =C527*C$3 -> 0 | X527: =D527*D$3 -> -9180 | Y527: =E527*E$3 -> -3445 | Z527: =F527*F$3 -> 10870 | AA527: =G527*G$3 -> -10000 | AB527: =H527*H$3 -> 31948 | AC527: =I527*I$3 -> -28899 | ... AM527: =S527*S$3 -> 53153.513 | AN527: =SUM(V527:AM527) -> -257417.87 | AO527: =AN527/AN528-1 -> -2.3453311
A528: 45327 | B528: =(B1078-B1077)*100 -> 0 | C528: =(C1078-C1077)*100 -> 1 | D528: =(D1078-D1077)*100 -> 1 | E528: =(E1078-E1077)*100 -> 0 | F528: =(F1078-F1077)*100 -> -3 | G528: =(G1078-G1077)*100 -> -6 | H528: =(H1078-H1077)*100 -> -10 | I528: =(I1078-I1077)*100 -> -13 | ... N528: =(N1078-N1077)*100 -> -13 | O528: =LN(O1077/O1078) -> 0.01169651 | P528: =LN(P1077/P1078) -> 0.0045618171 | Q528: =LN(Q1077/Q1078) -> 0.0083305001 | R528: =LN(R1077/R1078) -> 0.0080614141 | S528: =LN(S1077/S1078) -> 0 | U528: 45327 | V528: =B528*B$3 -> 0 | W528: =C528*C$3 -> -2223 | X528: =D528*D$3 -> 4590 | Y528: =E528*E$3 -> 0 | Z528: =F528*F$3 -> -16305 | AA528: =G528*G$3 -> 12000 | AB528: =H528*H$3 -> -45640 | AC528: =I528*I$3 -> 28899 | ... AM528: =S528*S$3 -> 0 | AN528: =SUM(V528:AM528) -> 191341.65 | AO528: =AN528/AN529-1 -> -0.62813072
A529: 45324 | B529: =(B1079-B1078)*100 -> 0 | C529: =(C1079-C1078)*100 -> 0 | D529: =(D1079-D1078)*100 -> -1 | E529: =(E1079-E1078)*100 -> -4 | F529: =(F1079-F1078)*100 -> -7 | G529: =(G1079-G1078)*100 -> -13 | H529: =(H1079-H1078)*100 -> -16 | I529: =(I1079-I1078)*100 -> -18 | ... N529: =(N1079-N1078)*100 -> -12 | O529: =LN(O1078/O1079) -> 0.0024490221 | P529: =LN(P1078/P1079) -> 0.012774861 | Q529: =LN(Q1078/Q1079) -> 0.0040144144 | R529: =LN(R1078/R1079) -> 0.0052356141 | S529: =LN(S1078/S1079) -> 0.0032361354 | U529: 45324 | V529: =B529*B$3 -> 0 | W529: =C529*C$3 -> 0 | X529: =D529*D$3 -> -4590 | Y529: =E529*E$3 -> 13780 | Z529: =F529*F$3 -> -38045 | AA529: =G529*G$3 -> 26000 | AB529: =H529*H$3 -> -73024 | AC529: =I529*I$3 -> 40014 | ... AM529: =S529*S$3 -> -32361.354 | AN529: =SUM(V529:AM529) -> 514540.07 | AO529: =AN529/AN530-1 -> -6.081429
A530: 45323 | B530: =(B1080-B1079)*100 -> 4 | C530: =(C1080-C1079)*100 -> -5 | D530: =(D1080-D1079)*100 -> 0 | E530: =(E1080-E1079)*100 -> 2 | F530: =(F1080-F1079)*100 -> 3 | G530: =(G1080-G1079)*100 -> 5 | H530: =(H1080-H1079)*100 -> 7 | I530: =(I1080-I1079)*100 -> 9 | ... N530: =(N1080-N1079)*100 -> 12 | O530: =LN(O1079/O1080) -> -0.0037419516 | P530: =LN(P1079/P1080) -> -0.0057970136 | Q530: =LN(Q1079/Q1080) -> -0.00042897283 | R530: =LN(R1079/R1080) -> 0.00052507221 | S530: =LN(S1079/S1080) -> -0.002460184 | U530: 45323 | V530: =B530*B$3 -> -16000 | W530: =C530*C$3 -> 11115 | X530: =D530*D$3 -> 0 | Y530: =E530*E$3 -> -6890 | Z530: =F530*F$3 -> 16305 | AA530: =G530*G$3 -> -10000 | AB530: =H530*H$3 -> 31948 | AC530: =I530*I$3 -> -20007 | ... AM530: =S530*S$3 -> 24601.84 | AN530: =SUM(V530:AM530) -> -101258.93 | AO530: =AN530/AN531-1 -> -0.67342823
A531: 45322 | B531: =(B1081-B1080)*100 -> 0 | C531: =(C1081-C1080)*100 -> 1 | D531: =(D1081-D1080)*100 -> 0 | E531: =(E1081-E1080)*100 -> -2 | F531: =(F1081-F1080)*100 -> 1 | G531: =(G1081-G1080)*100 -> 7 | H531: =(H1081-H1080)*100 -> 9 | I531: =(I1081-I1080)*100 -> 9 | ... N531: =(N1081-N1080)*100 -> 6 | O531: =LN(O1080/O1081) -> -0.0020773047 | P531: =LN(P1080/P1081) -> -0.0017241494 | Q531: =LN(Q1080/Q1081) -> 0.0054077722 | R531: =LN(R1080/R1081) -> 0.00026263953 | S531: =LN(S1080/S1081) -> -0.00086925836 | U531: 45322 | V531: =B531*B$3 -> 0 | W531: =C531*C$3 -> -2223 | X531: =D531*D$3 -> 0 | Y531: =E531*E$3 -> 6890 | Z531: =F531*F$3 -> 5435 | AA531: =G531*G$3 -> -14000 | AB531: =H531*H$3 -> 41076 | AC531: =I531*I$3 -> -20007 | ... AM531: =S531*S$3 -> 8692.5836 | AN531: =SUM(V531:AM531) -> -310066.4 | AO531: =AN531/AN532-1 -> -1.4745297
A532: 45321 | B532: =(B1082-B1081)*100 -> 0 | C532: =(C1082-C1081)*100 -> -1 | D532: =(D1082-D1081)*100 -> 0 | E532: =(E1082-E1081)*100 -> -1 | F532: =(F1082-F1081)*100 -> 0 | G532: =(G1082-G1081)*100 -> -4 | H532: =(H1082-H1081)*100 -> -7 | I532: =(I1082-I1081)*100 -> -4 | ... N532: =(N1082-N1081)*100 -> 3 | O532: =LN(O1081/O1082) -> 0.008355552 | P532: =LN(P1081/P1082) -> -0.0032231996 | Q532: =LN(Q1081/Q1082) -> 0.012441924 | R532: =LN(R1081/R1082) -> -0.0005252101 | S532: =LN(S1081/S1082) -> -0.0040097941 | U532: 45321 | V532: =B532*B$3 -> 0 | W532: =C532*C$3 -> 2223 | X532: =D532*D$3 -> 0 | Y532: =E532*E$3 -> 3445 | Z532: =F532*F$3 -> 0 | AA532: =G532*G$3 -> 8000 | AB532: =H532*H$3 -> -31948 | AC532: =I532*I$3 -> 8892 | ... AM532: =S532*S$3 -> 40097.941 | AN532: =SUM(V532:AM532) -> 653418.27 | AO532: =AN532/AN533-1 -> -2.9801881
A533: 45320 | B533: =(B1083-B1082)*100 -> 1 | C533: =(C1083-C1082)*100 -> -1 | D533: =(D1083-D1082)*100 -> 2 | E533: =(E1083-E1082)*100 -> 2 | F533: =(F1083-F1082)*100 -> 0 | G533: =(G1083-G1082)*100 -> 2 | H533: =(H1083-H1082)*100 -> 5 | I533: =(I1083-I1082)*100 -> 5 | ... N533: =(N1083-N1082)*100 -> 7 | O533: =LN(O1082/O1083) -> 0.0020336784 | P533: =LN(P1082/P1083) -> 0.0066360631 | Q533: =LN(Q1082/Q1083) -> 0.005681056 | R533: =LN(R1082/R1083) -> 0.0044731031 | S533: =LN(S1082/S1083) -> 0.0042547435 | U533: 45320 | V533: =B533*B$3 -> -4000 | W533: =C533*C$3 -> 2223 | X533: =D533*D$3 -> 9180 | Y533: =E533*E$3 -> -6890 | Z533: =F533*F$3 -> 0 | AA533: =G533*G$3 -> -4000 | AB533: =H533*H$3 -> 22820 | AC533: =I533*I$3 -> -11115 | ... AM533: =S533*S$3 -> -42547.435 | AN533: =SUM(V533:AM533) -> -329977.88 | AO533: =AN533/AN534-1 -> -2.661791
A534: 45317 | B534: =(B1084-B1083)*100 -> 0 | C534: =(C1084-C1083)*100 -> 3 | D534: =(D1084-D1083)*100 -> 0 | E534: =(E1084-E1083)*100 -> 0 | F534: =(F1084-F1083)*100 -> 0 | G534: =(G1084-G1083)*100 -> -2 | H534: =(H1084-H1083)*100 -> -6 | I534: =(I1084-I1083)*100 -> -3 | ... N534: =(N1084-N1083)*100 -> 0 | O534: =LN(O1083/O1084) -> -0.0021758811 | P534: =LN(P1083/P1084) -> -0.0096992883 | Q534: =LN(Q1083/Q1084) -> 0.0027040709 | R534: =LN(R1083/R1084) -> 0.0076770728 | S534: =LN(S1083/S1084) -> -0.0038539058 | U534: 45317 | V534: =B534*B$3 -> 0 | W534: =C534*C$3 -> -6669 | X534: =D534*D$3 -> 0 | Y534: =E534*E$3 -> 0 | Z534: =F534*F$3 -> 0 | AA534: =G534*G$3 -> 4000 | AB534: =H534*H$3 -> -27384 | AC534: =I534*I$3 -> 6669 | ... AM534: =S534*S$3 -> 38539.058 | AN534: =SUM(V534:AM534) -> 198567.61 | AO534: =AN534/AN535-1 -> -1.6485509
A535: 45316 | B535: =(B1085-B1084)*100 -> -2 | C535: =(C1085-C1084)*100 -> -4 | D535: =(D1085-D1084)*100 -> 0 | E535: =(E1085-E1084)*100 -> 1 | F535: =(F1085-F1084)*100 -> 3 | G535: =(G1085-G1084)*100 -> 7 | H535: =(H1085-H1084)*100 -> 6 | I535: =(I1085-I1084)*100 -> 7 | ... N535: =(N1085-N1084)*100 -> 3 | O535: =LN(O1084/O1085) -> 0.00081285948 | P535: =LN(P1084/P1085) -> 0.0079083194 | Q535: =LN(Q1084/Q1085) -> -0.00039617472 | R535: =LN(R1084/R1085) -> 0.001063547 | S535: =LN(S1084/S1085) -> -0.00013363042 | U535: 45316 | V535: =B535*B$3 -> 8000 | W535: =C535*C$3 -> 8892 | X535: =D535*D$3 -> 0 | Y535: =E535*E$3 -> -3445 | Z535: =F535*F$3 -> 16305 | AA535: =G535*G$3 -> -14000 | AB535: =H535*H$3 -> 27384 | AC535: =I535*I$3 -> -15561 | ... AM535: =S535*S$3 -> 1336.3042 | AN535: =SUM(V535:AM535) -> -306171.23 | AO535: =AN535/AN536-1 -> 8.3726749
A536: 45315 | B536: =(B1086-B1085)*100 -> 1 | C536: =(C1086-C1085)*100 -> 2 | D536: =(D1086-D1085)*100 -> 1 | E536: =(E1086-E1085)*100 -> -2 | F536: =(F1086-F1085)*100 -> -1 | G536: =(G1086-G1085)*100 -> -2 | H536: =(H1086-H1085)*100 -> -3 | I536: =(I1086-I1085)*100 -> -3 | ... N536: =(N1086-N1085)*100 -> -3 | O536: =LN(O1085/O1086) -> -0.010576331 | P536: =LN(P1085/P1086) -> -0.012561368 | Q536: =LN(Q1085/Q1086) -> 0.0035712355 | R536: =LN(R1085/R1086) -> -0.0021259641 | S536: =LN(S1085/S1086) -> -0.0060873556 | U536: 45315 | V536: =B536*B$3 -> -4000 | W536: =C536*C$3 -> -4446 | X536: =D536*D$3 -> 4590 | Y536: =E536*E$3 -> 6890 | Z536: =F536*F$3 -> -5435 | AA536: =G536*G$3 -> 4000 | AB536: =H536*H$3 -> -13692 | AC536: =I536*I$3 -> 6669 | ... AM536: =S536*S$3 -> 60873.556 | AN536: =SUM(V536:AM536) -> -32666.366 | AO536: =AN536/AN537-1 -> -0.91484433
A537: 45314 | B537: =(B1087-B1086)*100 -> 0 | C537: =(C1087-C1086)*100 -> 1 | D537: =(D1087-D1086)*100 -> 1 | E537: =(E1087-E1086)*100 -> 1 | F537: =(F1087-F1086)*100 -> 1 | G537: =(G1087-G1086)*100 -> 2 | H537: =(H1087-H1086)*100 -> 6 | I537: =(I1087-I1086)*100 -> -2 | ... N537: =(N1087-N1086)*100 -> -6 | O537: =LN(O1086/O1087) -> 0.0045363438 | P537: =LN(P1086/P1087) -> 0.014480386 | Q537: =LN(Q1086/Q1087) -> -0.0056156416 | R537: =LN(R1086/R1087) -> 0.0074607327 | S537: =LN(S1086/S1087) -> 0.0077677497 | U537: 45314 | V537: =B537*B$3 -> 0 | W537: =C537*C$3 -> -2223 | X537: =D537*D$3 -> 4590 | Y537: =E537*E$3 -> -3445 | Z537: =F537*F$3 -> 5435 | AA537: =G537*G$3 -> -4000 | AB537: =H537*H$3 -> 27384 | AC537: =I537*I$3 -> 4446 | ... AM537: =S537*S$3 -> -77677.497 | AN537: =SUM(V537:AM537) -> -383607.64 | AO537: =AN537/AN538-1 -> 0.094365162
... A549: 45295 | B549: =(B1099-B1098)*100 -> -2 | C549: =(C1099-C1098)*100 -> 6 | D549: =(D1099-D1098)*100 -> 0 | E549: =(E1099-E1098)*100 -> 0 | F549: =(F1099-F1098)*100 -> 0 | G549: =(G1099-G1098)*100 -> -4 | H549: =(H1099-H1098)*100 -> -5 | I549: =(I1099-I1098)*100 -> -7 | ... N549: =(N1099-N1098)*100 -> -8 | O549: =LN(O1098/O1099) -> -0.00048783463 | P549: =LN(P1098/P1099) -> 0.0031232247 | Q549: =LN(Q1098/Q1099) -> 0.0039313259 | R549: =LN(R1098/R1099) -> -0.0021453481 | S549: =LN(S1098/S1099) -> -9.3920966e-05 | U549: 45295 | V549: =B549*B$3 -> 8000 | W549: =C549*C$3 -> -13338 | X549: =D549*D$3 -> 0 | Y549: =E549*E$3 -> 0 | Z549: =F549*F$3 -> 0 | AA549: =G549*G$3 -> 8000 | AB549: =H549*H$3 -> -22820 | AC549: =I549*I$3 -> 15561 | ... AM549: =S549*S$3 -> 939.20966 | AN549: =SUM(V549:AM549) -> 131358.88 | AO549: =AN549/AN550-1 -> -1.4753783
A550: 45294 | B550: =(B1100-B1099)*100 -> 1 | C550: =(C1100-C1099)*100 -> 0 | D550: =(D1100-D1099)*100 -> -2 | E550: =(E1100-E1099)*100 -> 0 | F550: =(F1100-F1099)*100 -> -1 | G550: =(G1100-G1099)*100 -> -1 | H550: =(H1100-H1099)*100 -> 0 | I550: =(I1100-I1099)*100 -> 2 | ... N550: =(N1100-N1099)*100 -> 3 | O550: =LN(O1099/O1100) -> 0.0060333238 | P550: =LN(P1099/P1100) -> 0.010894052 | Q550: =LN(Q1099/Q1100) -> 0.0043230028 | R550: =LN(R1099/R1100) -> 0.0077988831 | S550: =LN(S1099/S1100) -> -0.00044600416 | U550: 45294 | V550: =B550*B$3 -> -4000 | W550: =C550*C$3 -> 0 | X550: =D550*D$3 -> -9180 | Y550: =E550*E$3 -> 0 | Z550: =F550*F$3 -> -5435 | AA550: =G550*G$3 -> 2000 | AB550: =H550*H$3 -> 0 | AC550: =I550*I$3 -> -4446 | ... AM550: =S550*S$3 -> 4460.0416 | AN550: =SUM(V550:AM550) -> -276324.93
A551: 45293 | U551: 45293
A553: dates | B553: 1mo | C553: 2mo | D553: 3mo | E553: 4mo | F553: 6mo | G553: 1y | H553: 2y | I553: 3y | J553: 5y | K553: 7y | L553: 10y | M553: 20y | N553: 30y | O553: USDBRL | P553: USDCOP | Q553: USDCLP | R553: USDPEN | S553: USDMXN
A554: 46093 | B554: 3.76 | C554: 3.72 | D554: 3.72 | E554: 3.69 | F554: 3.7 | G554: 3.66 | H554: 3.76 | I554: 3.75 | J554: 3.88 | K554: 4.06 | L554: 4.27 | M554: 4.86 | N554: 4.88 | O554: 5.2048 | P554: 3683 | Q554: 895.86 | R554: 3.445 | S554: 17.8449
A555: 46092 | B555: 3.75 | C555: 3.7 | D555: 3.71 | E555: 3.69 | F555: 3.68 | G555: 3.6 | H555: 3.64 | I555: 3.64 | J555: 3.79 | K555: 3.98 | L555: 4.21 | M555: 4.82 | N555: 4.86 | O555: 5.1593 | P555: 3704.9 | Q555: 893.69 | R555: 3.419 | S555: 17.6698
A556: 46091 | B556: 3.75 | C556: 3.71 | D556: 3.71 | E556: 3.69 | F556: 3.68 | G556: 3.56 | H556: 3.57 | I556: 3.58 | J556: 3.73 | K556: 3.93 | L556: 4.15 | M556: 4.74 | N556: 4.78 | O556: 5.1619 | P556: 3697.05 | Q556: 916.36 | R556: 3.423 | S556: 17.5903
A557: 46090 | B557: 3.75 | C557: 3.72 | D557: 3.71 | E557: 3.68 | F557: 3.68 | G557: 3.56 | H557: 3.56 | I557: 3.58 | J557: 3.71 | K557: 3.9 | L557: 4.12 | M557: 4.7 | N557: 4.72 | O557: 5.2136 | P557: 3767 | Q557: 921.76 | R557: 3.488 | S557: 17.6711
A558: 46087 | B558: 3.75 | C558: 3.72 | D558: 3.69 | E558: 3.67 | F558: 3.66 | G558: 3.55 | H558: 3.56 | I558: 3.59 | J558: 3.72 | K558: 3.93 | L558: 4.15 | M558: 4.74 | N558: 4.77 | O558: 5.2875 | P558: 3770 | Q558: 907.66 | R558: 3.478 | S558: 17.8034
A559: 46086 | B559: 3.75 | C559: 3.72 | D559: 3.7 | E559: 3.68 | F559: 3.68 | G559: 3.59 | H559: 3.57 | I559: 3.59 | J559: 3.72 | K559: 3.92 | L559: 4.13 | M559: 4.71 | N559: 4.74 | O559: 5.2444 | P559: 3775 | Q559: 895.14 | R559: 3.439 | S559: 17.79
...
