Workbook

Sheet Dash
B1: 0.94 EWMA CoVaR (2y Lookback, OW last 11 obs) | J1: Half Life: Number of days until the following obs go to 0.5 weight
F2: Delta | G2: CoVaR
B3: c Multiplier | C3: =Risk!C2 -> 666190.7 | E3: Latam FX | F3: =SUM(C13:C17)*100 -> -15000000 | G3: =SUM(D13:D17) -> 77852.582 | H3: =G3/$C$3 -> 0.11686231 | M3: =LN(0.5)/LN(0.94) -> 11.202306
B4: 99% CoVaR | C4: =C3*-2.326 -> -1549559.6 | E4: G10 FX | F4: =SUM(C19:C23)*100 -> 12000000 | G4: =SUM(D19:D23) -> -10281.74 | H4: =G4/$C$3 -> -0.015433628
B5: 99% Hist VaR (1y) | C5: =Hist!B1 -> -1916578.1
B6: 99% Hist VaR (All) | C6: =Hist!B2 -> -2040256.2 | E6: USD Parll | F6: =SUM(C27:C40) -> -126093.5 | G6: =SUM(D27:D40) -> 598619.85 | H6: =G6/$C$3 -> 0.89857132
E7: 0-1Y | F7: =SUM(C27:C32) -> -13052 | G7: =SUM(D27:D32) -> 43865.186 | H7: =G7/$C$3 -> 0.065844789
E8: 1-5Y | F8: =SUM(C33:C36) -> -97723.5 | G8: =SUM(D33:D36) -> 434912.76 | H8: =G8/$C$3 -> 0.65283524
E9: 5-10Y | F9: =SUM(C37:C38) -> -47391 | G9: =SUM(D37:D38) -> 215114.24 | H9: =G9/$C$3 -> 0.3229019
E10: 10-30Y | F10: =SUM(C39:C40) -> 32073 | G10: =SUM(D39:D40) -> -95272.337 | H10: =G10/$C$3 -> -0.14301061
B11: FX (in USD)
B12: Latam FX | C12: FX 1% Delta | D12: Allocation | E12: %Allocation | H12: Min Trade | I12: c Reduc | J12: %c Reduc | K12: m c x 1mio | M12: Q*S | N12: diag(Q)
B13: USDBRL | C13: 0 | D13: =(C13*M13)/$C$3 -> 0 | E13: =D13/$C$3 -> 0 | H13: =-M13/N13 -> 287604.24 | I13: =$C$3-SQRT($C$3^2-(M13^2)/N13) -> 40020.887 | J13: =I13/$C$3 -> 0.06007422 | K13: =(-1000*M13)/$C$3 -> 269.94577 | M13: =Risk!M24 -> -179835.36 | N13: =Risk!N24 -> 0.62528758
B14: USDCOP | C14: -50000 | D14: =(C14*M14)/$C$3 -> 6806.1777 | E14: =D14/$C$3 -> 0.010216561 | H14: =-M14/N14 -> 63942.371 | I14: =$C$3-SQRT($C$3^2-(M14^2)/N14) -> 4366.3403 | J14: =I14/$C$3 -> 0.0065541899 | K14: =(-1000*M14)/$C$3 -> 136.12355 | M14: =Risk!M25 -> -90684.246 | N14: =Risk!N25 -> 1.4182184
B15: USDCLP | C15: 120000 | D15: =(C15*M15)/$C$3 -> 17508.831 | E15: =D15/$C$3 -> 0.02628201 | H15: =-M15/N15 -> -79902.171 | I15: =$C$3-SQRT($C$3^2-(M15^2)/N15) -> 5854.868 | J15: =I15/$C$3 -> 0.0087885766 | K15: =(-1000*M15)/$C$3 -> -145.90692 | M15: =Risk!M26 -> 97201.835 | N15: =Risk!N26 -> 1.2165106
B16: USDPEN | C16: -150000 | D16: =(C16*M16)/$C$3 -> 30596.248 | E16: =D16/$C$3 -> 0.045927162 | H16: =-M16/N16 -> 322172.31 | I16: =$C$3-SQRT($C$3^2-(M16^2)/N16) -> 33710.452 | J16: =I16/$C$3 -> 0.050601805 | K16: =(-1000*M16)/$C$3 -> 203.97499 | M16: =Risk!M27 -> -135886.24 | N16: =Risk!N27 -> 0.42178125
B17: USDMXN | C17: -70000 | D17: =(C17*M17)/$C$3 -> 22941.326 | E17: =D17/$C$3 -> 0.034436575 | H17: =-M17/N17 -> 456362.07 | I17: =$C$3-SQRT($C$3^2-(M17^2)/N17) -> 79529.615 | J17: =I17/$C$3 -> 0.11937965 | K17: =(-1000*M17)/$C$3 -> 327.73322 | M17: =Risk!M28 -> -218332.82 | N17: =Risk!N28 -> 0.47842018
B18: G10 FX | C18: FX 1% Delta | D18: Allocation | E18: %Allocation | H18: Min Trade | I18: c Reduc | J18: %c Reduc | K18: m c x 1mio | M18: Q*S | N18: diag(Q)
B19: USDEUR | C19: 40000 | D19: =(C19*M19)/$C$3 -> -4599.5784 | E19: =D19/$C$3 -> -0.0069042969 | H19: =-M19/N19 -> 160120.56 | I19: =$C$3-SQRT($C$3^2-(M19^2)/N19) -> 9270.5925 | J19: =I19/$C$3 -> 0.013915824 | K19: =(-1000*M19)/$C$3 -> 114.98946 | M19: =Risk!M29 -> -76604.908 | N19: =Risk!N28 -> 0.47842018
B20: USDGBP | C20: 80000 | D20: =(C20*M20)/$C$3 -> -5682.1612 | E20: =D20/$C$3 -> -0.0085293314 | H20: =-M20/N20 -> 98903.723 | I20: =$C$3-SQRT($C$3^2-(M20^2)/N20) -> 3521.7267 | J20: =I20/$C$3 -> 0.0052863642 | K20: =(-1000*M20)/$C$3 -> 71.027015 | M20: =Risk!M30 -> -47317.537 | N20: =Risk!N29 -> 0.47842018
B21: USDJPY | C21: 0 | D21: =(C21*M21)/$C$3 -> 0 | E21: =D21/$C$3 -> 0 | H21: =-M21/N21 -> 158654.61 | I21: =$C$3-SQRT($C$3^2-(M21^2)/N21) -> 9100.4495 | J21: =I21/$C$3 -> 0.013660427 | K21: =(-1000*M21)/$C$3 -> 113.9367 | M21: =Risk!M31 -> -75903.569 | N21: =Risk!N30 -> 0.47842018
B22: USDAUD | C22: 0 | D22: =(C22*M22)/$C$3 -> 0 | E22: =D22/$C$3 -> 0 | H22: =-M22/N22 -> -102041.46 | I22: =$C$3-SQRT($C$3^2-(M22^2)/N22) -> 3749.3682 | J22: =I22/$C$3 -> 0.0056280705 | K22: =(-1000*M22)/$C$3 -> -73.280359 | M22: =Risk!M32 -> 48818.693 | N22: =Risk!N31 -> 0.47842018
B23: USDCHF | C23: 0 | D23: =(C23*M23)/$C$3 -> 0 | E23: =D23/$C$3 -> 0 | H23: =-M23/N23 -> 67057.042 | I23: =$C$3-SQRT($C$3^2-(M23^2)/N23) -> 1616.5791 | J23: =I23/$C$3 -> 0.0024266011 | K23: =(-1000*M23)/$C$3 -> 48.156544 | M23: =Risk!M33 -> -32081.442 | N23: =Risk!N32 -> 0.47842018
B25: US Swaps (in USD)
B26: STIR | C26: DV01 | D26: Allocation | E26: %Allocation | H26: Min Trade | I26: c Reduc | J26: %c Reduc | K26: m c x 10k | M26: Q*S | N26: diag(Q)
B27: 1mo | C27: -983 | D27: =(C27*M27)/$C$3 -> 162.87602 | E27: =D27/$C$3 -> 0.00024448858 | H27: =-M27/N27 -> 76910.867 | I27: =$C$3-SQRT($C$3^2-(M27^2)/N27) -> 6402.5546 | J27: =I27/$C$3 -> 0.0096106936 | K27: =(-10000*M27)/$C$3 -> 1656.9279 | M27: =Risk!M11 -> -110383 | N27: =Risk!N11 -> 1.4352068
B28: 2mo | C28: -2584 | D28: =(C28*M28)/$C$3 -> 403.57173 | E28: =D28/$C$3 -> 0.0006057901 | H28: =-M28/N28 -> 49074.536 | I28: =$C$3-SQRT($C$3^2-(M28^2)/N28) -> 3843.3416 | J28: =I28/$C$3 -> 0.0057691314 | K28: =(-10000*M28)/$C$3 -> 1561.8101 | M28: =Risk!M12 -> -104046.34 | N28: =Risk!N12 -> 2.1201695
B29: 3mo | C29: 16143 | D29: =(C29*M29)/$C$3 -> -9512.0371 | E29: =D29/$C$3 -> -0.01427825 | H29: =-M29/N29 -> 162801.39 | I29: =$C$3-SQRT($C$3^2-(M29^2)/N29) -> 49827.647 | J29: =I29/$C$3 -> 0.074794871 | K29: =(-10000*M29)/$C$3 -> 5892.3602 | M29: =Risk!M13 -> -392543.56 | N29: =Risk!N13 -> 2.4111806
B30: 4mo | C30: 2428 | D30: =(C30*M30)/$C$3 -> -539.5501 | E30: =D30/$C$3 -> -0.00080990339 | H30: =-M30/N30 -> 132416.92 | I30: =$C$3-SQRT($C$3^2-(M30^2)/N30) -> 14879 | J30: =I30/$C$3 -> 0.022334445 | K30: =(-10000*M30)/$C$3 -> 2222.1998 | M30: =Risk!M14 -> -148040.88 | N30: =Risk!N14 -> 1.1179907
B31: 6mo | C31: -12428 | D31: =(C31*M31)/$C$3 -> 13362.514 | E31: =D31/$C$3 -> 0.020058091 | H31: =-M31/N31 -> 185902.84 | I31: =$C$3-SQRT($C$3^2-(M31^2)/N31) -> 108830.18 | J31: =I31/$C$3 -> 0.16336191 | K31: =(-10000*M31)/$C$3 -> 10751.942 | M31: =Risk!M15 -> -716284.38 | N31: =Risk!N15 -> 3.8530039
B32: 1y | C32: -15628 | D32: =(C32*M32)/$C$3 -> 39987.812 | E32: =D32/$C$3 -> 0.060024572 | H32: =-M32/N32 -> 179030.29 | I32: =$C$3-SQRT($C$3^2-(M32^2)/N32) -> 293853.77 | J32: =I32/$C$3 -> 0.44109558 | K32: =(-10000*M32)/$C$3 -> 25587.287 | M32: =Risk!M16 -> -1704601.2 | N32: =Risk!N16 -> 9.5213006
B33: 2y | C33: -28216 | D33: =(C33*M33)/$C$3 -> 127259.08 | E33: =D33/$C$3 -> 0.191025 | H33: =-M33/N33 -> 127449.25 | I33: =$C$3-SQRT($C$3^2-(M33^2)/N33) -> 419469.39 | J33: =I33/$C$3 -> 0.62965363 | K33: =(-10000*M33)/$C$3 -> 45101.744 | M33: =Risk!M17 -> -3004636.2 | N33: =Risk!N17 -> 23.575157
B34: LT Rates | C34: DV01 | D34: Allocation | E34: %Allocation | H34: Min Trade | I34: c Reduc | J34: %c Reduc | K34: m c x 1mio | M34: Q*S | N34: diag(Q)
B35: 3y | C35: -18456 | D35: =(C35*M35)/$C$3 -> 83685.02 | E35: =D35/$C$3 -> 0.12561722 | H35: =-M35/N35 -> 129887.56 | I35: =$C$3-SQRT($C$3^2-(M35^2)/N35) -> 439347.86 | J35: =I35/$C$3 -> 0.65949263 | K35: =(-10000*M35)/$C$3 -> 45342.989 | M35: =Risk!M18 -> -3020707.7 | N35: =Risk!N18 -> 23.256328
B36: 5y | C36: -51051.5 | D36: =(C36*M36)/$C$3 -> 223968.66 | E36: =D36/$C$3 -> 0.33619302 | H36: =-M36/N36 -> 132154.11 | I36: =$C$3-SQRT($C$3^2-(M36^2)/N36) -> 426254.49 | J36: =I36/$C$3 -> 0.63983855 | K36: =(-10000*M36)/$C$3 -> 43871.123 | M36: =Risk!M19 -> -2922653.4 | N36: =Risk!N19 -> 22.115494
B37: 7y | C37: -78395 | D37: =(C37*M37)/$C$3 -> 323574.77 | E37: =D37/$C$3 -> 0.48570894 | H37: =-M37/N37 -> 133312.35 | I37: =$C$3-SQRT($C$3^2-(M37^2)/N37) -> 388267.23 | J37: =I37/$C$3 -> 0.58281695 | K37: =(-10000*M37)/$C$3 -> 41274.925 | M37: =Risk!M20 -> -2749697.1 | N37: =Risk!N20 -> 20.625974
B38: 10y | C38: 31004 | D38: =(C38*M38)/$C$3 -> -108460.53 | E38: =D38/$C$3 -> -0.16280704 | H38: =-M38/N38 -> 143306.7 | I38: =$C$3-SQRT($C$3^2-(M38^2)/N38) -> 334782.91 | J38: =I38/$C$3 -> 0.50253314 | K38: =(-10000*M38)/$C$3 -> 34982.755 | M38: =Risk!M21 -> -2330518.6 | N38: =Risk!N21 -> 16.262454
B39: 20y | C39: 32073 | D39: =(C39*M39)/$C$3 -> -95272.337 | E39: =D39/$C$3 -> -0.14301061 | H39: =-M39/N39 -> 129117.5 | I39: =$C$3-SQRT($C$3^2-(M39^2)/N39) -> 232257.19 | J39: =I39/$C$3 -> 0.3486347 | K39: =(-10000*M39)/$C$3 -> 29704.841 | M39: =Risk!M22 -> -1978908.9 | N39: =Risk!N22 -> 15.326419
B40: 30y | C40: 0 | D40: =(C40*M40)/$C$3 -> 0 | E40: =D40/$C$3 -> 0 | H40: =-M40/N40 -> 106779.72 | I40: =$C$3-SQRT($C$3^2-(M40^2)/N40) -> 148220.35 | J40: =I40/$C$3 -> 0.22248936 | K40: =(-10000*M40)/$C$3 -> 24673.528 | M40: =Risk!M23 -> -1643727.5 | N40: =Risk!N23 -> 15.39363
C42: Total Risk | D42: =SUM(D13:D40) -> 666190.7 | E42: =SUM(E13:E40) -> 1

Sheet Risk
P1: eqw | Q1: ewma | R1: rie
A2: CoVaR Multiplier (c) | C2: {=SQRT(MMULT(TRANSPOSE(C11:C33),_xlfn.ANCHORARRAY(M11)))} -> 666190.7 | E2: 330174.53 | F2: =C2-E2 -> 336016.17 | O2: CoVaR Multiplier (c) | P2: 198545.56 | Q2: 299271.2 | R2: 205307
B3: 99% VaR | C3: =C2*2.326 -> 1549559.6 | O3: 99% CoVaR | P3: 461816.98 | Q3: 696104.82 | R3: 477544.09
O4: 95% CoVaR | P4: 326408.91 | Q4: 492001.86 | R4: 337524.71
A5: 1Y | B5: Hist 99% | C5: =Hist!B1*-1 -> 1916578.1 | O5: Hist 99% 300 obs | P5: =C5 -> 1916578.1
A6: all | B6: Hist 99% | C6: =Hist!B2*-1 -> 2040256.2 | O6: Hist 99% 546 obs | P6: =C6 -> 2040256.2
O7: 99% Last 300 obs Hist vs CoVar | P7: =P3-$C5 -> -1454761.1 | Q7: =Q3-$C5 -> -1220473.3 | R7: =R3-$C5 -> -1439034
O8: 99% Last 546 obs Hist vs CoVar | P8: =P3-$C6 -> -1578439.2 | Q8: =Q3-$C6 -> -1344151.4 | R8: =R3-$C6 -> -1562712.1
A10: Type | B10: Bucket | C10: Risk | D10: Allocation | E10: %Allocation | F10: marginal c x 1k/1mio | I10: Min Trade | J10: c Reduc | K10: %c Reduc | M10: Q*S | N10: diag(Q)
A11: USD Swap | B11: 1mo | C11: =Dash!C27 -> -983 | D11: =(C11*M11)/$C$2 -> 162.87602 | E11: =+D11/$C$2 -> 0.00024448858 | F11: =(-1000*M11)/$C$2 -> 165.69279 | I11: =-M11/N11 -> 76910.867 | J11: =$C$2-SQRT($C$2^2-(M11^2)/N11) -> 6402.5546 | K11: =J11/$C$2 -> 0.0096106936 | M11: {=MMULT(Q!B2:X24,C11:C33)} -> -110383 | N11: 1.4352068
A12: USD Swap | B12: 2mo | C12: =Dash!C28 -> -2584 | D12: =(C12*M12)/$C$2 -> 403.57173 | E12: =+D12/$C$2 -> 0.0006057901 | F12: =(-1000*M12)/$C$2 -> 156.18101 | I12: =-M12/N12 -> 49074.536 | J12: =$C$2-SQRT($C$2^2-(M12^2)/N12) -> 3843.3416 | K12: =J12/$C$2 -> 0.0057691314 | M12: -104046.34 | N12: 2.1201695
A13: USD Swap | B13: 3mo | C13: =Dash!C29 -> 16143 | D13: =(C13*M13)/$C$2 -> -9512.0371 | E13: =+D13/$C$2 -> -0.01427825 | F13: =(-1000*M13)/$C$2 -> 589.23602 | I13: =-M13/N13 -> 162801.39 | J13: =$C$2-SQRT($C$2^2-(M13^2)/N13) -> 49827.647 | K13: =J13/$C$2 -> 0.074794871 | M13: -392543.56 | N13: 2.4111806
A14: USD Swap | B14: 4mo | C14: =Dash!C30 -> 2428 | D14: =(C14*M14)/$C$2 -> -539.5501 | E14: =+D14/$C$2 -> -0.00080990339 | F14: =(-1000*M14)/$C$2 -> 222.21998 | I14: =-M14/N14 -> 132416.92 | J14: =$C$2-SQRT($C$2^2-(M14^2)/N14) -> 14879 | K14: =J14/$C$2 -> 0.022334445 | M14: -148040.88 | N14: 1.1179907
A15: USD Swap | B15: 6mo | C15: =Dash!C31 -> -12428 | D15: =(C15*M15)/$C$2 -> 13362.514 | E15: =+D15/$C$2 -> 0.020058091 | F15: =(-1000*M15)/$C$2 -> 1075.1942 | I15: =-M15/N15 -> 185902.84 | J15: =$C$2-SQRT($C$2^2-(M15^2)/N15) -> 108830.18 | K15: =J15/$C$2 -> 0.16336191 | M15: -716284.38 | N15: 3.8530039
A16: USD Swap | B16: 1y | C16: =Dash!C32 -> -15628 | D16: =(C16*M16)/$C$2 -> 39987.812 | E16: =+D16/$C$2 -> 0.060024572 | F16: =(-1000*M16)/$C$2 -> 2558.7287 | I16: =-M16/N16 -> 179030.29 | J16: =$C$2-SQRT($C$2^2-(M16^2)/N16) -> 293853.77 | K16: =J16/$C$2 -> 0.44109558 | M16: -1704601.2 | N16: 9.5213006
A17: USD Swap | B17: 2y | C17: =Dash!C33 -> -28216 | D17: =(C17*M17)/$C$2 -> 127259.08 | E17: =+D17/$C$2 -> 0.191025 | F17: =(-1000*M17)/$C$2 -> 4510.1744 | I17: =-M17/N17 -> 127449.25 | J17: =$C$2-SQRT($C$2^2-(M17^2)/N17) -> 419469.39 | K17: =J17/$C$2 -> 0.62965363 | M17: -3004636.2 | N17: 23.575157
A18: USD Swap | B18: 3y | C18: =Dash!C35 -> -18456 | D18: =(C18*M18)/$C$2 -> 83685.02 | E18: =+D18/$C$2 -> 0.12561722 | F18: =(-1000*M18)/$C$2 -> 4534.2989 | I18: =-M18/N18 -> 129887.56 | J18: =$C$2-SQRT($C$2^2-(M18^2)/N18) -> 439347.86 | K18: =J18/$C$2 -> 0.65949263 | M18: -3020707.7 | N18: 23.256328
A19: USD Swap | B19: 5y | C19: =Dash!C36 -> -51051.5 | D19: =(C19*M19)/$C$2 -> 223968.66 | E19: =+D19/$C$2 -> 0.33619302 | F19: =(-1000*M19)/$C$2 -> 4387.1123 | I19: =-M19/N19 -> 132154.11 | J19: =$C$2-SQRT($C$2^2-(M19^2)/N19) -> 426254.49 | K19: =J19/$C$2 -> 0.63983855 | M19: -2922653.4 | N19: 22.115494
A20: USD Swap | B20: 7y | C20: =Dash!C37 -> -78395 | D20: =(C20*M20)/$C$2 -> 323574.77 | E20: =+D20/$C$2 -> 0.48570894 | F20: =(-1000*M20)/$C$2 -> 4127.4925 | I20: =-M20/N20 -> 133312.35 | J20: =$C$2-SQRT($C$2^2-(M20^2)/N20) -> 388267.23 | K20: =J20/$C$2 -> 0.58281695 | M20: -2749697.1 | N20: 20.625974
A21: USD Swap | B21: 10y | C21: =Dash!C38 -> 31004 | D21: =(C21*M21)/$C$2 -> -108460.53 | E21: =+D21/$C$2 -> -0.16280704 | F21: =(-1000*M21)/$C$2 -> 3498.2755 | I21: =-M21/N21 -> 143306.7 | J21: =$C$2-SQRT($C$2^2-(M21^2)/N21) -> 334782.91 | K21: =J21/$C$2 -> 0.50253314 | M21: -2330518.6 | N21: 16.262454
A22: USD Swap | B22: 20y | C22: =Dash!C39 -> 32073 | D22: =(C22*M22)/$C$2 -> -95272.337 | E22: =+D22/$C$2 -> -0.14301061 | F22: =(-1000*M22)/$C$2 -> 2970.4841 | I22: =-M22/N22 -> 129117.5 | J22: =$C$2-SQRT($C$2^2-(M22^2)/N22) -> 232257.19 | K22: =J22/$C$2 -> 0.3486347 | M22: -1978908.9 | N22: 15.326419
A23: USD Swap | B23: 30y | C23: =Dash!C40 -> 0 | D23: =(C23*M23)/$C$2 -> 0 | E23: =+D23/$C$2 -> 0 | F23: =(-1000*M23)/$C$2 -> 2467.3528 | I23: =-M23/N23 -> 106779.72 | J23: =$C$2-SQRT($C$2^2-(M23^2)/N23) -> 148220.35 | K23: =J23/$C$2 -> 0.22248936 | M23: -1643727.5 | N23: 15.39363
A24: FX | B24: USDBRL | C24: =Dash!C13 -> 0 | D24: =(C24*M24)/$C$2 -> 0 | E24: =+D24/$C$2 -> 0 | F24: =(-1000*M24)/$C$2 -> 269.94577 | I24: =-M24/N24 -> 287604.24 | J24: =$C$2-SQRT($C$2^2-(M24^2)/N24) -> 40020.887 | K24: =J24/$C$2 -> 0.06007422 | M24: -179835.36 | N24: 0.62528758
A25: FX | B25: USDCOP | C25: =Dash!C14 -> -50000 | D25: =(C25*M25)/$C$2 -> 6806.1777 | E25: =+D25/$C$2 -> 0.010216561 | F25: =(-1000*M25)/$C$2 -> 136.12355 | I25: =-M25/N25 -> 63942.371 | J25: =$C$2-SQRT($C$2^2-(M25^2)/N25) -> 4366.3403 | K25: =J25/$C$2 -> 0.0065541899 | M25: -90684.246 | N25: 1.4182184
A26: FX | B26: USDCLP | C26: =Dash!C15 -> 120000 | D26: =(C26*M26)/$C$2 -> 17508.831 | E26: =+D26/$C$2 -> 0.02628201 | F26: =(-1000*M26)/$C$2 -> -145.90692 | I26: =-M26/N26 -> -79902.171 | J26: =$C$2-SQRT($C$2^2-(M26^2)/N26) -> 5854.868 | K26: =J26/$C$2 -> 0.0087885766 | M26: 97201.835 | N26: 1.2165106
A27: FX | B27: USDPEN | C27: =Dash!C16 -> -150000 | D27: =(C27*M27)/$C$2 -> 30596.248 | E27: =+D27/$C$2 -> 0.045927162 | F27: =(-1000*M27)/$C$2 -> 203.97499 | I27: =-M27/N27 -> 322172.31 | J27: =$C$2-SQRT($C$2^2-(M27^2)/N27) -> 33710.452 | K27: =J27/$C$2 -> 0.050601805 | M27: -135886.24 | N27: 0.42178125
A28: FX | B28: USDMXN | C28: =Dash!C17 -> -70000 | D28: =(C28*M28)/$C$2 -> 22941.326 | E28: =+D28/$C$2 -> 0.034436575 | F28: =(-1000*M28)/$C$2 -> 327.73322 | I28: =-M28/N28 -> 456362.07 | J28: =$C$2-SQRT($C$2^2-(M28^2)/N28) -> 79529.615 | K28: =J28/$C$2 -> 0.11937965 | M28: -218332.82 | N28: 0.47842018
A29: FX | B29: USDEUR | C29: =Dash!C19 -> 40000 | D29: =(C29*M29)/$C$2 -> -4599.5784 | E29: =+D29/$C$2 -> -0.0069042969 | F29: =(-1000*M29)/$C$2 -> 114.98946 | I29: =-M29/N29 -> 160120.56 | J29: =$C$2-SQRT($C$2^2-(M29^2)/N29) -> 9270.5925 | K29: =J29/$C$2 -> 0.013915824 | M29: -76604.908 | N29: 0.47842018
A30: FX | B30: USDGBP | C30: =Dash!C20 -> 80000 | D30: =(C30*M30)/$C$2 -> -5682.1612 | E30: =+D30/$C$2 -> -0.0085293314 | F30: =(-1000*M30)/$C$2 -> 71.027015 | I30: =-M30/N30 -> 98903.723 | J30: =$C$2-SQRT($C$2^2-(M30^2)/N30) -> 3521.7267 | K30: =J30/$C$2 -> 0.0052863642 | M30: -47317.537 | N30: 0.47842018
A31: FX | B31: USDJPY | C31: =Dash!C21 -> 0 | D31: =(C31*M31)/$C$2 -> 0 | E31: =+D31/$C$2 -> 0 | F31: =(-1000*M31)/$C$2 -> 113.9367 | I31: =-M31/N31 -> 158654.61 | J31: =$C$2-SQRT($C$2^2-(M31^2)/N31) -> 9100.4495 | K31: =J31/$C$2 -> 0.013660427 | M31: -75903.569 | N31: 0.47842018
A32: FX | B32: USDAUD | C32: =Dash!C22 -> 0 | D32: =(C32*M32)/$C$2 -> 0 | E32: =+D32/$C$2 -> 0 | F32: =(-1000*M32)/$C$2 -> -73.280359 | I32: =-M32/N32 -> -102041.46 | J32: =$C$2-SQRT($C$2^2-(M32^2)/N32) -> 3749.3682 | K32: =J32/$C$2 -> 0.0056280705 | M32: 48818.693 | N32: 0.47842018
A33: FX | B33: USDCHF | C33: =Dash!C23 -> 0 | D33: =(C33*M33)/$C$2 -> 0 | E33: =+D33/$C$2 -> 0 | F33: =(-1000*M33)/$C$2 -> 48.156544 | I33: =-M33/N33 -> 67057.042 | J33: =$C$2-SQRT($C$2^2-(M33^2)/N33) -> 1616.5791 | K33: =J33/$C$2 -> 0.0024266011 | M33: -32081.442 | N33: 0.47842018
A36: real risk | C36: std | E36: STIR | F36: DV01
A37: -983 | B37: 1mo | C37: -4000 | E37: 1mo | F37: -983
A38: -2584 | B38: 2mo | C38: -2223 | E38: 2mo | F38: -2584
A39: 26143 | B39: 3mo | C39: 4590 | E39: 3mo | F39: 26143
A40: 2428 | B40: 4mo | C40: -3445 | E40: 4mo | F40: 2428
A41: 12428 | B41: 6mo | C41: 5435 | E41: 6mo | F41: 12428
A42: -25628 | B42: 1y | C42: -2000 | E42: 1y | F42: -25628
A43: 38216 | B43: 2y | C43: 4564 | E43: 2y | F43: 38216
...

Sheet Q
B1: 1mo | C1: 2mo | D1: 3mo | E1: 4mo | F1: 6mo | G1: 1y | H1: 2y | I1: 3y | J1: 5y | K1: 7y | L1: 10y | M1: 20y | N1: 30y | O1: USDBRL | P1: USDCOP | Q1: USDCLP | R1: USDPEN | S1: USDMXN | T1: USDEUR | U1: USDGBP | V1: USDJPY | W1: USDAUD | X1: USDCHF
A2: 1mo | B2: 1.4352068 | C2: 0.71559403 | D2: 0.28725654 | E2: 0.22367614 | F2: 0.068100075 | G2: 0.35063582 | H2: 0.52161864 | I2: 0.53362192 | J2: 0.27183172 | K2: 0.13539027 | L2: -0.03674077 | M2: -0.27440652 | N2: -0.58282893 | O2: 0.12562727 | P2: 0.33922941 | Q2: -0.060095522 | R2: 0.10710348 | S2: 0.14345151 | T2: 0.063559652 | U2: 0.0094800357 | V2: 0.11068185 | W2: -0.069076901 | X2: 0.12140905
A3: 2mo | B3: 0.71559403 | C3: 2.1201695 | D3: 0.75240879 | E3: 0.2749326 | F3: 0.51441232 | G3: 0.83032075 | H3: 1.1131113 | I3: 1.1734039 | J3: 0.51587879 | K3: 0.23485984 | L3: 0.00064348763 | M3: -0.67510851 | N3: -0.90968579 | O3: 0.021422523 | P3: 0.1675174 | Q3: 0.32538114 | R3: 0.11344612 | S3: -0.029098081 | T3: 0.15706216 | U3: 0.077049094 | V3: 0.25755131 | W3: 0.11702399 | X3: 0.075077502
A4: 3mo | B4: 0.28725654 | C4: 0.75240879 | D4: 2.4111806 | E4: 0.79910394 | F4: 2.3338225 | G4: 2.5084867 | H4: 3.5782707 | I4: 3.5371317 | J4: 3.6654033 | K4: 3.1019776 | L4: 2.3717489 | M4: 1.682762 | N4: 1.3029264 | O4: -0.08365038 | P4: -0.30393002 | Q4: 0.43502168 | R4: -0.033058402 | S4: -0.12635742 | T4: 0.18522222 | U4: 0.21824333 | V4: 0.21506438 | W4: 0.20417057 | X4: -0.042291787
A5: 4mo | B5: 0.22367614 | C5: 0.2749326 | D5: 0.79910394 | E5: 1.1179907 | F5: 0.96358575 | G5: 1.295868 | H5: 1.4651771 | I5: 1.4500788 | J5: 1.5907532 | K5: 1.247977 | L5: 0.90825076 | M5: 0.63041082 | N5: 0.62213527 | O5: -0.26789166 | P5: -0.089806925 | Q5: 0.12465396 | R5: -0.198267 | S5: -0.24543362 | T5: -0.0087214 | U5: 0.028161505 | V5: -0.055255427 | W5: 0.023112137 | X5: -0.086617156
A6: 6mo | B6: 0.068100075 | C6: 0.51441232 | D6: 2.3338225 | E6: 0.96358575 | F6: 3.8530039 | G6: 4.0201477 | H6: 5.6726295 | I6: 5.6035234 | J6: 5.7111237 | K6: 4.9258685 | L6: 3.8127522 | M6: 2.9655384 | N6: 2.4443085 | O6: 0.12537733 | P6: -0.225098 | Q6: 0.5109687 | R6: 0.083872215 | S6: 0.058461523 | T6: 0.20815491 | U6: 0.24329095 | V6: 0.15278325 | W6: 0.17797092 | X6: -0.14833332
A7: 1y | B7: 0.35063582 | C7: 0.83032075 | D7: 2.5084867 | E7: 1.295868 | F7: 4.0201477 | G7: 9.5213006 | H7: 13.180848 | I7: 13.109375 | J7: 12.048578 | K7: 10.585496 | L7: 8.5498965 | M7: 6.8363463 | N7: 5.7145259 | O7: 0.040013075 | P7: -0.15352504 | Q7: 0.17624832 | R7: 0.15508244 | S7: 0.42259018 | T7: 0.52431448 | U7: 0.38145836 | V7: 0.4250268 | W7: 0.04593341 | X7: 0.22953341
A8: 2y | B8: 0.52161864 | C8: 1.1131113 | D8: 3.5782707 | E8: 1.4651771 | F8: 5.6726295 | G8: 13.180848 | H8: 23.575157 | I8: 22.321996 | J8: 21.374197 | K8: 19.678458 | L8: 16.700193 | M8: 14.289667 | N8: 12.017395 | O8: 0.82373895 | P8: -0.60453093 | Q8: 0.27339761 | R8: 0.76149006 | S8: 1.2116792 | T8: 0.86168787 | U8: 0.63030054 | V8: 0.79139618 | W8: -0.013887328 | X8: 0.5327349
A9: 3y | B9: 0.53362192 | C9: 1.1734039 | D9: 3.5371317 | E9: 1.4500788 | F9: 5.6035234 | G9: 13.109375 | H9: 22.321996 | I9: 23.256328 | J9: 22.047672 | K9: 20.645032 | L9: 17.514106 | M9: 14.661103 | N9: 12.519987 | O9: 0.69946227 | P9: -0.55078428 | Q9: 0.349042 | R9: 0.69578142 | S9: 0.91795622 | T9: 0.8786451 | U9: 0.63316884 | V9: 0.83868004 | W9: 0.3078369 | X9: 0.44343125
A10: 5y | B10: 0.27183172 | C10: 0.51587879 | D10: 3.6654033 | E10: 1.5907532 | F10: 5.7111237 | G10: 12.048578 | H10: 21.374197 | I10: 22.047672 | J10: 22.115494 | K10: 20.978807 | L10: 18.03392 | M10: 15.753548 | N10: 13.931889 | O10: 0.69649641 | P10: -0.7020328 | Q10: 0.1787057 | R10: 0.47918026 | S10: 0.84498147 | T10: 0.67895028 | U10: 0.52237459 | V10: 0.63054493 | W10: 0.17323316 | X10: 0.27205055
A11: 7y | B11: 0.13539027 | C11: 0.23485984 | D11: 3.1019776 | E11: 1.247977 | F11: 4.9258685 | G11: 10.585496 | H11: 19.678458 | I11: 20.645032 | J11: 20.978807 | K11: 20.625974 | L11: 17.932341 | M11: 15.915839 | N11: 14.519913 | O11: 0.76715763 | P11: -0.72594993 | Q11: 0.0959062 | R11: 0.375818 | S11: 0.85655752 | T11: 0.50574764 | U11: 0.38354712 | V11: 0.53479391 | W11: 0.092710814 | X11: 0.20309151
A12: 10y | B12: -0.03674077 | C12: 0.00064348763 | D12: 2.3717489 | E12: 0.90825076 | F12: 3.8127522 | G12: 8.5498965 | H12: 16.700193 | I12: 17.514106 | J12: 18.03392 | K12: 17.932341 | L12: 16.262454 | M12: 14.961847 | N12: 14.034064 | O12: 0.66128549 | P12: -0.61093901 | Q12: -0.18435586 | R12: 0.28964251 | S12: 0.7666543 | T12: 0.36522034 | U12: 0.26101923 | V12: 0.4842198 | W12: -0.043502902 | X12: 0.17021118
A13: 20y | B13: -0.27440652 | C13: -0.67510851 | D13: 1.682762 | E13: 0.63041082 | F13: 2.9655384 | G13: 6.8363463 | H13: 14.289667 | I13: 14.661103 | J13: 15.753548 | K13: 15.915839 | L13: 14.961847 | M13: 15.326419 | N13: 14.822194 | O13: 0.61929367 | P13: -0.73505452 | Q13: -0.67997965 | R13: 0.11706534 | S13: 0.71722812 | T13: 0.15979474 | U13: 0.13250106 | V13: 0.27905756 | W13: -0.26024327 | X13: 0.10233138
... A24: USDCHF | B24: 0.12140905 | C24: 0.075077502 | D24: -0.042291787 | E24: -0.086617156 | F24: -0.14833332 | G24: 0.22953341 | H24: 0.5327349 | I24: 0.44343125 | J24: 0.27205055 | K24: 0.20309151 | L24: 0.17021118 | M24: 0.10233138 | N24: -0.0077687582 | O24: 0.1014735 | P24: -0.020420605 | Q24: 0.17922988 | R24: 0.12220869 | S24: 0.086034158 | T24: 0.17518596 | U24: 0.12690611 | V24: 0.14864648 | W24: 0.1261707 | X24: 0.24881533

Sheet Hist
A1: Hist VaR | B1: =SMALL(AX5:AX304,4) -> -1916578.1
A2: Hist VaR | B2: =SMALL(AX5:AX550,4) -> -2040256.2
A3: Risk | B3: {=TRANSPOSE(Risk!C11:C23)} -> -983 | C3: -2584 | D3: 16143 | E3: 2428 | F3: -12428 | G3: -15628 | H3: -28216 | I3: -18456 | J3: -51051.5 | K3: -78395 | L3: 31004 | M3: 32073 | N3: 0 | O3: {=TRANSPOSE(Risk!C24:C33)/0.01} -> 0 | P3: -5000000 | Q3: 12000000 | R3: -15000000 | S3: -7000000 | T3: 4000000 | U3: 8000000 | V3: 0 | W3: 0 | X3: 0 | BB3: all | BC3: 1y
A4: dates | B4: 1mo | C4: 2mo | D4: 3mo | E4: 4mo | F4: 6mo | G4: 1y | H4: 2y | I4: 3y | J4: 5y | K4: 7y | L4: 10y | M4: 20y | N4: 30y | O4: USDBRL | P4: USDCOP | Q4: USDCLP | R4: USDPEN | S4: USDMXN | T4: USDEUR | U4: USDGBP | V4: USDJPY | W4: USDAUD | X4: USDCHF | Z4: dates | AA4: 1mo | AB4: 2mo | AC4: 3mo | AD4: 4mo | AE4: 6mo | AF4: 1y | AG4: 2y | AH4: 3y | AI4: 5y | AJ4: 7y | AK4: 10y | AL4: 20y | AM4: 30y | AN4: USDBRL | AO4: USDCOP | AP4: USDCLP | AQ4: USDPEN | AR4: USDMXN | AS4: USDEUR | AT4: USDGBP | AU4: USDJPY | AV4: USDAUD | AW4: USDCHF | AX4: PnL | AY4: fx | AZ4: ir | BA4: 6 | BB4: =SMALL($AX$5:$AX$550,BA4) -> -1916578.1 | BC4: =SMALL($AX$5:$AX$304,BA4) -> -1399680.8
A5: 46093 | B5: =(B554-B555)*100 -> 1 | C5: =(C554-C555)*100 -> 2 | D5: =(D554-D555)*100 -> 1 | E5: =(E554-E555)*100 -> 0 | F5: =(F554-F555)*100 -> 2 | G5: =(G554-G555)*100 -> 6 | H5: =(H554-H555)*100 -> 12 | I5: =(I554-I555)*100 -> 11 | ... N5: =(N554-N555)*100 -> 2 | O5: =LN(O554/O555) -> 0.0087803654 | P5: =LN(P554/P555) -> -0.0059286304 | Q5: =LN(Q554/Q555) -> 0.0024251919 | R5: =LN(R554/R555) -> 0.0075757938 | S5: =LN(S554/S555) -> 0.0098607855 | T5: =LN(T554/T555) -> 0.005881167 | U5: =LN(U554/U555) -> 0.0027739264 | V5: =LN(V554/V555) -> 0.0060594881 | ... X5: =LN(X554/X555) -> 0.0040530594 | Z5: 46093 | AA5: =B5*B$3 -> -983 | AB5: =C5*C$3 -> -5168 | AC5: =D5*D$3 -> 16143 | AD5: =E5*E$3 -> 0 | AE5: =F5*F$3 -> -24856 | AF5: =G5*G$3 -> -93768 | AG5: =H5*H$3 -> -338592 | AH5: =I5*I$3 -> -203016 | ... AW5: =X5*X$3 -> 0 | AX5: =SUM(AA5:AW5) -> -1500748.4 | AY5: =SUM(AN5:AW5) -> -78200.872 | AZ5: =AX5-AY5 -> -1422547.5 | BA5: 5 | BB5: =SMALL($AX$5:$AX$550,BA5) -> -1964331.8 | BC5: =SMALL($AX$5:$AX$304,BA5) -> -1500748.4
A6: 46092 | B6: =(B556-B555)*100 -> 0 | C6: =(C556-C555)*100 -> 1 | D6: =(D556-D555)*100 -> 0 | E6: =(E556-E555)*100 -> 0 | F6: =(F556-F555)*100 -> 0 | G6: =(G556-G555)*100 -> -4 | H6: =(H556-H555)*100 -> -7 | I6: =(I556-I555)*100 -> -6 | ... N6: =(N556-N555)*100 -> -8 | O6: =LN(O555/O556) -> -0.0005038174 | P6: =LN(P555/P556) -> 0.0021210635 | Q6: =LN(Q555/Q556) -> -0.025050342 | R6: =LN(R555/R556) -> -0.0011692489 | S6: =LN(S555/S556) -> 0.0045093539 | T6: =LN(T555/T556) -> 0.0005110465 | U6: =LN(U555/U556) -> 0.00044283798 | V6: =LN(V555/V556) -> 0.0016836915 | ... X6: =LN(X555/X556) -> 0.00089687025 | Z6: 46092 | AA6: =B6*B$3 -> 0 | AB6: =C6*C$3 -> -2584 | AC6: =D6*D$3 -> 0 | AD6: =E6*E$3 -> 0 | AE6: =F6*F$3 -> 0 | AF6: =G6*G$3 -> 62512 | AG6: =H6*H$3 -> 197512 | AH6: =I6*I$3 -> 110736 | ... AW6: =X6*X$3 -> 0 | AX6: =SUM(AA6:AW6) -> 304202.73 | AY6: =SUM(AN6:AW6) -> -319649.27 | AZ6: =AX6-AY6 -> 623852 | BA6: 4 | BB6: =SMALL($AX$5:$AX$550,BA6) -> -2040256.2 | BC6: =SMALL($AX$5:$AX$304,BA6) -> -1916578.1
A7: 46091 | B7: =(B557-B556)*100 -> 0 | C7: =(C557-C556)*100 -> 1 | D7: =(D557-D556)*100 -> 0 | E7: =(E557-E556)*100 -> -1 | F7: =(F557-F556)*100 -> 0 | G7: =(G557-G556)*100 -> 0 | H7: =(H557-H556)*100 -> -1 | I7: =(I557-I556)*100 -> 0 | ... N7: =(N557-N556)*100 -> -6 | O7: =LN(O556/O557) -> -0.0099658673 | P7: =LN(P556/P557) -> -0.018743724 | Q7: =LN(Q556/Q557) -> -0.0058755854 | R7: =LN(R556/R557) -> -0.018811146 | S7: =LN(S556/S557) -> -0.0045829231 | T7: =LN(T556/T557) -> -0.0081221758 | U7: =LN(U556/U557) -> -0.0092738105 | V7: =LN(V556/V557) -> -0.0036613414 | ... X7: =LN(X556/X557) -> -0.0042845371 | Z7: 46091 | AA7: =B7*B$3 -> 0 | AB7: =C7*C$3 -> -2584 | AC7: =D7*D$3 -> 0 | AD7: =E7*E$3 -> -2428 | AE7: =F7*F$3 -> 0 | AF7: =G7*G$3 -> 0 | AG7: =H7*H$3 -> 28216 | AH7: =I7*I$3 -> 0 | ... AW7: =X7*X$3 -> 0 | AX7: =SUM(AA7:AW7) -> 369968.07 | AY7: =SUM(AN7:AW7) -> 230780.07 | AZ7: =AX7-AY7 -> 139188 | BA7: 3 | BB7: =SMALL($AX$5:$AX$550,BA7) -> -2974767.7 | BC7: =SMALL($AX$5:$AX$304,BA7) -> -1964331.8
A8: 46090 | B8: =(B558-B557)*100 -> 0 | C8: =(C558-C557)*100 -> 0 | D8: =(D558-D557)*100 -> -2 | E8: =(E558-E557)*100 -> -1 | F8: =(F558-F557)*100 -> -2 | G8: =(G558-G557)*100 -> -1 | H8: =(H558-H557)*100 -> 0 | I8: =(I558-I557)*100 -> 1 | ... N8: =(N558-N557)*100 -> 5 | O8: =LN(O557/O558) -> -0.014074948 | P8: =LN(P557/P558) -> -0.00079607275 | Q8: =LN(Q557/Q558) -> 0.015415027 | R8: =LN(R557/R558) -> 0.0028710901 | S8: =LN(S557/S558) -> -0.0074589135 | T8: =LN(T557/T558) -> 0.007332556 | U8: =LN(U557/U558) -> 0.0042253433 | V8: =LN(V557/V558) -> 0.0056526454 | ... X8: =LN(X557/X558) -> 0.00071714251 | Z8: 46090 | AA8: =B8*B$3 -> 0 | AB8: =C8*C$3 -> 0 | AC8: =D8*D$3 -> -32286 | AD8: =E8*E$3 -> -2428 | AE8: =F8*F$3 -> 24856 | AF8: =G8*G$3 -> 15628 | AG8: =H8*H$3 -> 0 | AH8: =I8*I$3 -> -18456 | ... AW8: =X8*X$3 -> 0 | AX8: =SUM(AA8:AW8) -> 183621.2 | AY8: =SUM(AN8:AW8) -> 261239.7 | AZ8: =AX8-AY8 -> -77618.5 | BA8: 2 | BB8: =SMALL($AX$5:$AX$550,BA8) -> -3495226.1 | BC8: =SMALL($AX$5:$AX$304,BA8) -> -2974767.7
A9: 46087 | B9: =(B559-B558)*100 -> 0 | C9: =(C559-C558)*100 -> 0 | D9: =(D559-D558)*100 -> 1 | E9: =(E559-E558)*100 -> 1 | F9: =(F559-F558)*100 -> 2 | G9: =(G559-G558)*100 -> 4 | H9: =(H559-H558)*100 -> 1 | I9: =(I559-I558)*100 -> 0 | ... N9: =(N559-N558)*100 -> -3 | O9: =LN(O558/O559) -> 0.0081847037 | P9: =LN(P558/P559) -> -0.0013253812 | Q9: =LN(Q558/Q559) -> 0.013889729 | R9: =LN(R558/R559) -> 0.011276684 | S9: =LN(S558/S559) -> 0.00075294862 | T9: =LN(T558/T559) -> 0.0023707822 | U9: =LN(U558/U559) -> 0.00090882554 | V9: =LN(V558/V559) -> 0.0035037562 | ... X9: =LN(X558/X559) -> 0.0019360883 | Z9: 46087 | AA9: =B9*B$3 -> 0 | AB9: =C9*C$3 -> 0 | AC9: =D9*D$3 -> 16143 | AD9: =E9*E$3 -> 2428 | AE9: =F9*F$3 -> -24856 | AF9: =G9*G$3 -> -62512 | AG9: =H9*H$3 -> -28216 | AH9: =I9*I$3 -> 0 | ... AW9: =X9*X$3 -> 0 | AX9: =SUM(AA9:AW9) -> -161208.53 | AY9: =SUM(AN9:AW9) -> 15636.474 | AZ9: =AX9-AY9 -> -176845 | BA9: 1 | BB9: =SMALL($AX$5:$AX$550,BA9) -> -3641163 | BC9: =SMALL($AX$5:$AX$304,BA9) -> -3495226.1
A10: 46086 | B10: =(B560-B559)*100 -> 0 | C10: =(C560-C559)*100 -> 3 | D10: =(D560-D559)*100 -> 1 | E10: =(E560-E559)*100 -> 0 | F10: =(F560-F559)*100 -> 0 | G10: =(G560-G559)*100 -> -1 | H10: =(H560-H559)*100 -> -3 | I10: =(I560-I559)*100 -> -4 | ... N10: =(N560-N559)*100 -> -2 | O10: =LN(O559/O560) -> 0.0068113377 | P10: =LN(P559/P560) -> 0.0074448629 | Q10: =LN(Q559/Q560) -> -0.012412314 | R10: =LN(R559/R560) -> 0.008175228 | S10: =LN(S559/S560) -> 0.013058473 | T10: =LN(T559/T560) -> -0.0020109002 | U10: =LN(U559/U560) -> -0.0011892759 | V10: =LN(V559/V560) -> -0.0050197293 | ... X10: =LN(X559/X560) -> -0.0035488601 | Z10: 46086 | AA10: =B10*B$3 -> 0 | AB10: =C10*C$3 -> -7752 | AC10: =D10*D$3 -> 16143 | AD10: =E10*E$3 -> 0 | AE10: =F10*F$3 -> 0 | AF10: =G10*G$3 -> 15628 | AG10: =H10*H$3 -> 84648 | AH10: =I10*I$3 -> 73824 | ... AW10: =X10*X$3 -> 0 | AX10: =SUM(AA10:AW10) -> 159647.88 | AY10: =SUM(AN10:AW10) -> -417767.62 | AZ10: =AX10-AY10 -> 577415.5
A11: 46085 | B11: =(B561-B560)*100 -> 0 | C11: =(C561-C560)*100 -> -1 | D11: =(D561-D560)*100 -> 0 | E11: =(E561-E560)*100 -> -1 | F11: =(F561-F560)*100 -> 0 | G11: =(G561-G560)*100 -> -3 | H11: =(H561-H560)*100 -> -3 | I11: =(I561-I560)*100 -> -5 | ... N11: =(N561-N560)*100 -> -2 | O11: =LN(O560/O561) -> -0.01484473 | P11: =LN(P560/P561) -> -0.014045547 | Q11: =LN(Q560/Q561) -> 0.024697854 | R11: =LN(R560/R561) -> -0.0011719896 | S11: =LN(S560/S561) -> -0.0044039292 | T11: =LN(T560/T561) -> 0.0072958326 | U11: =LN(U560/U561) -> 0.0042555898 | V11: =LN(V560/V561) -> 0.0032758256 | ... X11: =LN(X560/X561) -> 0.0041137395 | Z11: 46085 | AA11: =B11*B$3 -> 0 | AB11: =C11*C$3 -> 2584 | AC11: =D11*D$3 -> 0 | AD11: =E11*E$3 -> -2428 | AE11: =F11*F$3 -> 0 | AF11: =G11*G$3 -> 46884 | AG11: =H11*H$3 -> 84648 | AH11: =I11*I$3 -> 92280 | ... AW11: =X11*X$3 -> 0 | AX11: =SUM(AA11:AW11) -> 1062833.4 | AY11: =SUM(AN11:AW11) -> 478237.37 | AZ11: =AX11-AY11 -> 584596
A12: 46084 | B12: =(B562-B561)*100 -> -1 | C12: =(C562-C561)*100 -> 0 | D12: =(D562-D561)*100 -> 1 | E12: =(E562-E561)*100 -> 1 | F12: =(F562-F561)*100 -> 0 | G12: =(G562-G561)*100 -> -1 | H12: =(H562-H561)*100 -> -4 | I12: =(I562-I561)*100 -> -1 | ... N12: =(N562-N561)*100 -> 0 | O12: =LN(O561/O562) -> 0.016574069 | P12: =LN(P561/P562) -> 0.013511929 | Q12: =LN(Q561/Q562) -> 0.014582002 | R12: =LN(R561/R562) -> 0.01534406 | S12: =LN(S561/S562) -> 0.020125529 | T12: =LN(T561/T562) -> 0.005301247 | U12: =LN(U561/U562) -> -0.00029498709 | V12: =LN(V561/V562) -> 0.0039759725 | ... X12: =LN(X561/X562) -> 0.011858778 | Z12: 46084 | AA12: =B12*B$3 -> 983 | AB12: =C12*C$3 -> 0 | AC12: =D12*D$3 -> 16143 | AD12: =E12*E$3 -> 2428 | AE12: =F12*F$3 -> 0 | AF12: =G12*G$3 -> 15628 | AG12: =H12*H$3 -> 112864 | AH12: =I12*I$3 -> 18456 | ... AW12: =X12*X$3 -> 0 | AX12: =SUM(AA12:AW12) -> -11898.641 | AY12: =SUM(AN12:AW12) -> -244770.14 | AZ12: =AX12-AY12 -> 232871.5
A13: 46083 | B13: =(B563-B562)*100 -> 0 | C13: =(C563-C562)*100 -> -1 | D13: =(D563-D562)*100 -> -5 | E13: =(E563-E562)*100 -> -1 | F13: =(F563-F562)*100 -> -8 | G13: =(G563-G562)*100 -> -6 | H13: =(H563-H562)*100 -> -9 | I13: =(I563-I562)*100 -> -10 | ... N13: =(N563-N562)*100 -> -6 | O13: =LN(O562/O563) -> 0.0097788005 | P13: =LN(P562/P563) -> -0.00087984755 | Q13: =LN(Q562/Q563) -> 0.011797436 | R13: =LN(R562/R563) -> 0.0029779653 | S13: =LN(S562/S563) -> 0.0030999153 | T13: =LN(T562/T563) -> 0.0036992518 | U13: =LN(U562/U563) -> 0.0063074853 | V13: =LN(V562/V563) -> 0.0049537504 | ... X13: =LN(X562/X563) -> -0.0047966307 | Z13: 46083 | AA13: =B13*B$3 -> 0 | AB13: =C13*C$3 -> 2584 | AC13: =D13*D$3 -> -80715 | AD13: =E13*E$3 -> -2428 | AE13: =F13*F$3 -> 99424 | AF13: =G13*G$3 -> 93768 | AG13: =H13*H$3 -> 253944 | AH13: =I13*I$3 -> 184560 | ... AW13: =X13*X$3 -> 0 | AX13: =SUM(AA13:AW13) -> 1568967 | AY13: =SUM(AN13:AW13) -> 144856.47 | AZ13: =AX13-AY13 -> 1424110.5
A14: 46080 | B14: =(B564-B563)*100 -> 0 | C14: =(C564-C563)*100 -> 2 | D14: =(D564-D563)*100 -> 1 | E14: =(E564-E563)*100 -> 1 | F14: =(F564-F563)*100 -> 1 | G14: =(G564-G563)*100 -> 4 | H14: =(H564-H563)*100 -> 4 | I14: =(I564-I563)*100 -> 7 | ... N14: =(N564-N563)*100 -> 3 | O14: =LN(O563/O564) -> 0.0021969271 | P14: =LN(P563/P564) -> -0.020495818 | Q14: =LN(Q563/Q564) -> 0.0042006846 | R14: =LN(R563/R564) -> -0.00059630294 | S14: =LN(S563/S564) -> 0.0021378701 | T14: =LN(T563/T564) -> 0.0010274386 | U14: =LN(U563/U564) -> 0.0049229841 | V14: =LN(V563/V564) -> -0.002185507 | ... X14: =LN(X563/X564) -> 0.0014106528 | Z14: 46080 | AA14: =B14*B$3 -> 0 | AB14: =C14*C$3 -> -5168 | AC14: =D14*D$3 -> 16143 | AD14: =E14*E$3 -> 2428 | AE14: =F14*F$3 -> -12428 | AF14: =G14*G$3 -> -62512 | AG14: =H14*H$3 -> -112864 | AH14: =I14*I$3 -> -129192 | ... AW14: =X14*X$3 -> 0 | AX14: =SUM(AA14:AW14) -> -638672.62 | AY14: =SUM(AN14:AW14) -> 190360.38 | AZ14: =AX14-AY14 -> -829033
A15: 46079 | B15: =(B565-B564)*100 -> -3 | C15: =(C565-C564)*100 -> -2 | D15: =(D565-D564)*100 -> 1 | E15: =(E565-E564)*100 -> 0 | F15: =(F565-F564)*100 -> 1 | G15: =(G565-G564)*100 -> 1 | H15: =(H565-H564)*100 -> 3 | I15: =(I565-I564)*100 -> 3 | ... N15: =(N565-N564)*100 -> 3 | O15: =LN(O564/O565) -> -0.0011282292 | P15: =LN(P564/P565) -> 0.038051684 | Q15: =LN(Q564/Q565) -> -0.0090311362 | R15: =LN(R564/R565) -> 0 | S15: =LN(S564/S565) -> 0.0021599349 | T15: =LN(T564/T565) -> -0.003385308 | U15: =LN(U564/U565) -> -0.0044776649 | V15: =LN(V564/V565) -> 0.0020507061 | ... X15: =LN(X564/X565) -> -0.0020570351 | Z15: 46079 | AA15: =B15*B$3 -> 2949 | AB15: =C15*C$3 -> 5168 | AC15: =D15*D$3 -> 16143 | AD15: =E15*E$3 -> 0 | AE15: =F15*F$3 -> -12428 | AF15: =G15*G$3 -> -15628 | AG15: =H15*H$3 -> -84648 | AH15: =I15*I$3 -> -55368 | ... AW15: =X15*X$3 -> 0 | AX15: =SUM(AA15:AW15) -> -835481.15 | AY15: =SUM(AN15:AW15) -> -363114.15 | AZ15: =AX15-AY15 -> -472367
A16: 46078 | B16: =(B566-B565)*100 -> 1 | C16: =(C566-C565)*100 -> 0 | D16: =(D566-D565)*100 -> 0 | E16: =(E566-E565)*100 -> 2 | F16: =(F566-F565)*100 -> 0 | G16: =(G566-G565)*100 -> -1 | H16: =(H566-H565)*100 -> -2 | I16: =(I566-I565)*100 -> -2 | ... N16: =(N566-N565)*100 -> 0 | O16: =LN(O565/O566) -> -0.0046937516 | P16: =LN(P565/P566) -> -0.0046001975 | Q16: =LN(Q565/Q566) -> -0.0022278023 | R16: =LN(R565/R566) -> -0.00029801818 | S16: =LN(S565/S566) -> -0.0010135963 | T16: =LN(T565/T566) -> 0.001579168 | U16: =LN(U565/U566) -> -4.0451277e-05 | V16: =LN(V565/V566) -> 0.0080190461 | ... X16: =LN(X565/X566) -> -0.00064604174 | Z16: 46078 | AA16: =B16*B$3 -> -983 | AB16: =C16*C$3 -> 0 | AC16: =D16*D$3 -> 0 | AD16: =E16*E$3 -> 4856 | AE16: =F16*F$3 -> 0 | AF16: =G16*G$3 -> 15628 | AG16: =H16*H$3 -> 56432 | AH16: =I16*I$3 -> 36912 | ... AW16: =X16*X$3 -> 0 | AX16: =SUM(AA16:AW16) -> 174061.87 | AY16: =SUM(AN16:AW16) -> 13825.869 | AZ16: =AX16-AY16 -> 160236
A17: 46077 | B17: =(B567-B566)*100 -> 0 | C17: =(C567-C566)*100 -> 1 | D17: =(D567-D566)*100 -> 0 | E17: =(E567-E566)*100 -> 0 | F17: =(F567-F566)*100 -> 0 | G17: =(G567-G566)*100 -> -2 | H17: =(H567-H566)*100 -> 0 | I17: =(I567-I566)*100 -> -2 | ... N17: =(N567-N566)*100 -> 0 | O17: =LN(O566/O567) -> 0.00090987413 | P17: =LN(P566/P567) -> 0.0056042273 | Q17: =LN(Q566/Q567) -> 0.00018449972 | R17: =LN(R566/R567) -> -0.00059577005 | S17: =LN(S566/S567) -> -0.0052611529 | T17: =LN(T566/T567) -> 0.0034615685 | U17: =LN(U566/U567) -> 0.0026895356 | V17: =LN(V566/V567) -> 0.0019159546 | ... X17: =LN(X566/X567) -> 0.0032730861 | Z17: 46077 | AA17: =B17*B$3 -> 0 | AB17: =C17*C$3 -> -2584 | AC17: =D17*D$3 -> 0 | AD17: =E17*E$3 -> 0 | AE17: =F17*F$3 -> 0 | AF17: =G17*G$3 -> 31256 | AG17: =H17*H$3 -> 0 | AH17: =I17*I$3 -> 36912 | ... AW17: =X17*X$3 -> 0 | AX17: =SUM(AA17:AW17) -> 348793.04 | AY17: =SUM(AN17:AW17) -> 55320.04 | AZ17: =AX17-AY17 -> 293473
A18: 46076 | B18: =(B568-B567)*100 -> 0 | C18: =(C568-C567)*100 -> 0 | D18: =(D568-D567)*100 -> 0 | E18: =(E568-E567)*100 -> 1 | F18: =(F568-F567)*100 -> -1 | G18: =(G568-G567)*100 -> 1 | H18: =(H568-H567)*100 -> 5 | I18: =(I568-I567)*100 -> 5 | ... N18: =(N568-N567)*100 -> 2 | O18: =LN(O567/O568) -> -0.0071597739 | P18: =LN(P567/P568) -> -0.0092423099 | Q18: =LN(Q567/Q568) -> 0.00044986072 | R18: =LN(R567/R568) -> -0.00059541532 | S18: =LN(S567/S568) -> 0.007516931 | T18: =LN(T567/T568) -> -0.0055586994 | U18: =LN(U567/U568) -> -0.0053448783 | V18: =LN(V567/V568) -> -0.0053053551 | ... X18: =LN(X567/X568) -> -0.0047057641 | Z18: 46076 | AA18: =B18*B$3 -> 0 | AB18: =C18*C$3 -> 0 | AC18: =D18*D$3 -> 0 | AD18: =E18*E$3 -> 2428 | AE18: =F18*F$3 -> 12428 | AF18: =G18*G$3 -> -15628 | AG18: =H18*H$3 -> -141080 | AH18: =I18*I$3 -> -92280 | ... AW18: =X18*X$3 -> 0 | AX18: =SUM(AA18:AW18) -> -816643.23 | AY18: =SUM(AN18:AW18) -> -57071.233 | AZ18: =AX18-AY18 -> -759572
A19: 46073 | B19: =(B569-B568)*100 -> 0 | C19: =(C569-C568)*100 -> 1 | D19: =(D569-D568)*100 -> 0 | E19: =(E569-E568)*100 -> -1 | F19: =(F569-F568)*100 -> -1 | G19: =(G569-G568)*100 -> -1 | H19: =(H569-H568)*100 -> -1 | I19: =(I569-I568)*100 -> 0 | ... N19: =(N569-N568)*100 -> -2 | O19: =LN(O568/O569) -> -0.004805465 | P19: =LN(P568/P569) -> 0.0051402902 | Q19: =LN(Q568/Q569) -> 0.0039883754 | R19: =LN(R568/R569) -> 0.00059541532 | S19: =LN(S568/S569) -> -0.0081480339 | T19: =LN(T568/T569) -> 0.0016727173 | U19: =LN(U568/U569) -> 0.0025743468 | V19: =LN(V568/V569) -> 0.0030144027 | ... X19: =LN(X568/X569) -> 0.0040581007 | Z19: 46073 | AA19: =B19*B$3 -> 0 | AB19: =C19*C$3 -> -2584 | AC19: =D19*D$3 -> 0 | AD19: =E19*E$3 -> -2428 | AE19: =F19*F$3 -> 12428 | AF19: =G19*G$3 -> 15628 | AG19: =H19*H$3 -> 28216 | AH19: =I19*I$3 -> 0 | ... AW19: =X19*X$3 -> 0 | AX19: =SUM(AA19:AW19) -> 84663.706 | AY19: =SUM(AN19:AW19) -> 97549.706 | AZ19: =AX19-AY19 -> -12886
A20: 46072 | B20: =(B570-B569)*100 -> -1 | C20: =(C570-C569)*100 -> -2 | D20: =(D570-D569)*100 -> 1 | E20: =(E570-E569)*100 -> 0 | F20: =(F570-F569)*100 -> 0 | G20: =(G570-G569)*100 -> -1 | H20: =(H570-H569)*100 -> 0 | I20: =(I570-I569)*100 -> 0 | ... N20: =(N570-N569)*100 -> 1 | O20: =LN(O569/O570) -> -0.0017686514 | P20: =LN(P569/P570) -> 0.0047266547 | Q20: =LN(Q569/Q570) -> -0.0057175024 | R20: =LN(R569/R570) -> 0.0020867499 | S20: =LN(S569/S570) -> 0.0026022438 | T20: =LN(T569/T570) -> 0.0053308922 | U20: =LN(U569/U570) -> 0.0050737954 | V20: =LN(V569/V570) -> 0.010031146 | ... X20: =LN(X569/X570) -> 0.0025933291 | Z20: 46072 | AA20: =B20*B$3 -> 983 | AB20: =C20*C$3 -> 5168 | AC20: =D20*D$3 -> 16143 | AD20: =E20*E$3 -> 0 | AE20: =F20*F$3 -> 0 | AF20: =G20*G$3 -> 15628 | AG20: =H20*H$3 -> 0 | AH20: =I20*I$3 -> 0 | ... AW20: =X20*X$3 -> 0 | AX20: =SUM(AA20:AW20) -> -108293.83 | AY20: =SUM(AN20:AW20) -> -79846.326 | AZ20: =AX20-AY20 -> -28447.5
A21: 46071 | B21: =(B571-B570)*100 -> 1 | C21: =(C571-C570)*100 -> 0 | D21: =(D571-D570)*100 -> -1 | E21: =(E571-E570)*100 -> 0 | F21: =(F571-F570)*100 -> -1 | G21: =(G571-G570)*100 -> -1 | H21: =(H571-H570)*100 -> -4 | I21: =(I571-I570)*100 -> -3 | ... N21: =(N571-N570)*100 -> -3 | O21: =LN(O570/O571) -> 0.0011660026 | P21: =LN(P570/P571) -> 0.0087312969 | Q21: =LN(Q570/Q571) -> 0.0061577759 | R21: =LN(R570/R571) -> 0.0017921152 | S21: =LN(S570/S571) -> 0.0060010599 | T21: =LN(T570/T571) -> -0.00016597545 | U21: =LN(U570/U571) -> 0.0046498091 | V21: =LN(V570/V571) -> -0.0029990534 | ... X21: =LN(X570/X571) -> 0.00077937394 | Z21: 46071 | AA21: =B21*B$3 -> -983 | AB21: =C21*C$3 -> 0 | AC21: =D21*D$3 -> -16143 | AD21: =E21*E$3 -> 0 | AE21: =F21*F$3 -> 12428 | AF21: =G21*G$3 -> 15628 | AG21: =H21*H$3 -> 112864 | AH21: =I21*I$3 -> 55368 | ... AW21: =X21*X$3 -> 0 | AX21: =SUM(AA21:AW21) -> 455616.75 | AY21: =SUM(AN21:AW21) -> -2117.7504 | AZ21: =AX21-AY21 -> 457734.5
... A550: 45294 | B550: =(B1100-B1099)*100 -> 1 | C550: =(C1100-C1099)*100 -> 0 | D550: =(D1100-D1099)*100 -> -2 | E550: =(E1100-E1099)*100 -> 0 | F550: =(F1100-F1099)*100 -> -1 | G550: =(G1100-G1099)*100 -> -1 | H550: =(H1100-H1099)*100 -> 0 | I550: =(I1100-I1099)*100 -> 2 | ... N550: =(N1100-N1099)*100 -> 3 | O550: =LN(O1099/O1100) -> 0.0060333238 | P550: =LN(P1099/P1100) -> 0.010894052 | Q550: =LN(Q1099/Q1100) -> 0.0043230028 | R550: =LN(R1099/R1100) -> 0.0077988831 | S550: =LN(S1099/S1100) -> -0.00044600416 | T550: =LN(T1099/T1100) -> 0.0088250309 | U550: =LN(U1099/U1100) -> 0.00834079 | V550: =LN(V1099/V1100) -> 0.0072648445 | ... X550: =LN(X1099/X1100) -> 0.0097281878 | Z550: 45294 | AA550: =B550*B$3 -> -983 | AB550: =C550*C$3 -> 0 | AC550: =D550*D$3 -> -32286 | AD550: =E550*E$3 -> 0 | AE550: =F550*F$3 -> 12428 | AF550: =G550*G$3 -> 15628 | AG550: =H550*H$3 -> 0 | AH550: =I550*I$3 -> -36912 | ... AW550: =X550*X$3 -> 0 | AX550: =SUM(AA550:AW550) -> -192585.5 | AY550: =SUM(AN550:AW550) -> -14429.001 | AZ550: =AX550-AY550 -> -178156.5
A551: 45293 | Z551: 45293 | AZ551: =AX551-AY551 -> 0
A553: dates | B553: 1mo | C553: 2mo | D553: 3mo | E553: 4mo | F553: 6mo | G553: 1y | H553: 2y | I553: 3y | J553: 5y | K553: 7y | L553: 10y | M553: 20y | N553: 30y | O553: USDBRL | P553: USDCOP | Q553: USDCLP | R553: USDPEN | S553: USDMXN | T553: USDEUR | U553: USDGBP | V553: USDJPY | W553: USDAUD | X553: USDCHF
A554: 46093 | B554: 3.76 | C554: 3.72 | D554: 3.72 | E554: 3.69 | F554: 3.7 | G554: 3.66 | H554: 3.76 | I554: 3.75 | J554: 3.88 | K554: 4.06 | L554: 4.27 | M554: 4.86 | N554: 4.88 | O554: 5.2048 | P554: 3683 | Q554: 895.86 | R554: 3.445 | S554: 17.8449 | T554: 0.86631001 | U554: 0.74727999 | V554: 159.075 | W554: 1.40268 | X554: 0.78174001
A555: 46092 | B555: 3.75 | C555: 3.7 | D555: 3.71 | E555: 3.69 | F555: 3.68 | G555: 3.6 | H555: 3.64 | I555: 3.64 | J555: 3.79 | K555: 3.98 | L555: 4.21 | M555: 4.82 | N555: 4.86 | O555: 5.1593 | P555: 3704.9 | Q555: 893.69 | R555: 3.419 | S555: 17.6698 | T555: 0.86123004 | U555: 0.74520997 | V555: 158.114 | W555: 1.404297 | X555: 0.77857798
A556: 46091 | B556: 3.75 | C556: 3.71 | D556: 3.71 | E556: 3.69 | F556: 3.68 | G556: 3.56 | H556: 3.57 | I556: 3.58 | J556: 3.73 | K556: 3.93 | L556: 4.15 | M556: 4.74 | N556: 4.78 | O556: 5.1619 | P556: 3697.05 | Q556: 916.36 | R556: 3.423 | S556: 17.5903 | T556: 0.86079003 | U556: 0.74488003 | V556: 157.84801 | W556: 1.41471 | X556: 0.77788001
A557: 46090 | B557: 3.75 | C557: 3.72 | D557: 3.71 | E557: 3.68 | F557: 3.68 | G557: 3.56 | H557: 3.56 | I557: 3.58 | J557: 3.71 | K557: 3.9 | L557: 4.12 | M557: 4.7 | N557: 4.72 | O557: 5.2136 | P557: 3767 | Q557: 921.76 | R557: 3.488 | S557: 17.6711 | T557: 0.86780999 | U557: 0.75182004 | V557: 158.427 | W557: 1.435503 | X557: 0.78122002
A558: 46087 | B558: 3.75 | C558: 3.72 | D558: 3.69 | E558: 3.67 | F558: 3.66 | G558: 3.55 | H558: 3.56 | I558: 3.59 | J558: 3.72 | K558: 3.93 | L558: 4.15 | M558: 4.74 | N558: 4.77 | O558: 5.2875 | P558: 3770 | Q558: 907.66 | R558: 3.478 | S558: 17.8034 | T558: 0.86146999 | U558: 0.74865004 | V558: 157.534 | W558: 1.4262691 | X558: 0.78065997
A559: 46086 | B559: 3.75 | C559: 3.72 | D559: 3.7 | E559: 3.68 | F559: 3.68 | G559: 3.59 | H559: 3.57 | I559: 3.59 | J559: 3.72 | K559: 3.92 | L559: 4.13 | M559: 4.71 | N559: 4.74 | O559: 5.2444 | P559: 3775 | Q559: 895.14 | R559: 3.439 | S559: 17.79 | T559: 0.85943006 | U559: 0.74796996 | V559: 156.983 | W559: 1.4132281 | X559: 0.77915001
A560: 46085 | B560: 3.75 | C560: 3.75 | D560: 3.71 | E560: 3.68 | F560: 3.68 | G560: 3.58 | H560: 3.54 | I560: 3.55 | J560: 3.67 | K560: 3.87 | L560: 4.09 | M560: 4.67 | N560: 4.72 | O560: 5.2088 | P560: 3747 | Q560: 906.32 | R560: 3.411 | S560: 17.5592 | T560: 0.86116002 | U560: 0.74886003 | V560: 157.77299 | W560: 1.420313 | X560: 0.78192002
A561: 46084 | B561: 3.75 | C561: 3.74 | D561: 3.71 | E561: 3.67 | F561: 3.68 | G561: 3.55 | H561: 3.51 | I561: 3.5 | J561: 3.63 | K561: 3.83 | L561: 4.06 | M561: 4.65 | N561: 4.7 | O561: 5.2867 | P561: 3800 | Q561: 884.21 | R561: 3.415 | S561: 17.6367 | T561: 0.85490001 | U561: 0.74567996 | V561: 157.257 | W561: 1.407301 | X561: 0.77871001
A562: 46083 | B562: 3.74 | C562: 3.74 | D562: 3.72 | E562: 3.68 | F562: 3.68 | G562: 3.54 | H562: 3.47 | I562: 3.49 | J562: 3.62 | K562: 3.82 | L562: 4.05 | M562: 4.64 | N562: 4.7 | O562: 5.1998 | P562: 3749 | Q562: 871.41 | R562: 3.363 | S562: 17.2853 | T562: 0.85037996 | U562: 0.74589996 | V562: 156.633 | W562: 1.4168101 | X562: 0.76953
A563: 46080 | B563: 3.74 | C563: 3.73 | D563: 3.67 | E563: 3.67 | F563: 3.6 | G563: 3.48 | H563: 3.38 | I563: 3.39 | J563: 3.51 | K563: 3.72 | L563: 3.97 | M563: 4.57 | N563: 4.64 | O563: 5.1492 | P563: 3752.3 | Q563: 861.19 | R563: 3.353 | S563: 17.2318 | T563: 0.84724 | U563: 0.74121001 | V563: 155.85899 | W563: 1.408094 | X563: 0.77323002
A564: 46079 | B564: 3.74 | C564: 3.75 | D564: 3.68 | E564: 3.68 | F564: 3.61 | G564: 3.52 | H564: 3.42 | I564: 3.46 | J564: 3.57 | K564: 3.78 | L564: 4.02 | M564: 4.6 | N564: 4.67 | O564: 5.1379 | P564: 3830 | Q564: 857.58 | R564: 3.355 | S564: 17.195 | T564: 0.84636996 | U564: 0.73757001 | V564: 156.2 | W564: 1.4043961 | X564: 0.77214003
A565: 46078 | B565: 3.71 | C565: 3.73 | D565: 3.69 | E565: 3.68 | F565: 3.62 | G565: 3.53 | H565: 3.45 | I565: 3.49 | J565: 3.61 | K565: 3.82 | L565: 4.05 | M565: 4.63 | N565: 4.7 | O565: 5.1437 | P565: 3687 | Q565: 865.36 | R565: 3.355 | S565: 17.1579 | T565: 0.84924004 | U565: 0.74088001 | V565: 155.88 | W565: 1.41623 | X565: 0.77372998
... A1100: 45293 | B1100: 5.55 | C1100: 5.54 | D1100: 5.46 | E1100: 5.41 | F1100: 5.24 | G1100: 4.8 | H1100: 4.33 | I1100: 4.09 | J1100: 3.93 | K1100: 3.95 | L1100: 3.95 | M1100: 4.25 | N1100: 4.08 | O1100: 4.8913 | P1100: 3880 | Q1100: 877.12 | R1100: 3.704 | S1100: 17.044 | T1100: 0.90590003 | U1100: 0.78561996 | V1100: 141.12601 | W1100: 1.4683201 | X1100: 0.84188998
